Workbook

Sheet BASE
B19: CLIENTE: | C19: ='CUSTO NOVA'!H2 -> BRASCOLA LTDA -
B20: CNPJ:
B21: LOCAL REMETENTE:
B22: TIPO DE FRETE:

Sheet RESULTADO DIRETO
B3: COMPETENCIA | D3: TOTAL GERAL | L3: CUSTOS | P3: PESO 2024 | S3: 70449976
B4: FRETE | G4: CUSTOS | L4: Desp. Operacional | N4: 10313790 | P4: DESPESA ADMINISTRATIVA 2024 | S4: 15734290
B5: VALOR | D5: =VLOOKUP('RESULTADO DIRETO'!D3,FONTES!B5:I15,5,) -> 33465.1 | G5: Custo Operacional | I5: =VLOOKUP(D3,FONTES!B5:I15,8,) -> 22859.03 | L5: Carga e Descarga | N5: 4671731 | P5: RATEIO | S5: =S4/S3 -> 0.22333989
B6: Receita por kg | D6: =D5/D24 -> 2.4317564 | G6: Focal (agendamento) | L6: Motorista | N6: -2454302.6
B7: Tem Subst.Trib.? | G7: Seguro Acidente (0,014%) com iof | I7: =($D$25*0.01%)*7.38%+($D$25*0.01%) -> 36.439142 | L7: TOTAL | N7: =SUM(N4:N6) -> 12531218 | P7: FATURAMENTO | S7: 85634757
B8: Aliq. | C8: 0.12 | D8: =VLOOKUP('RESULTADO DIRETO'!D3,FONTES!B5:I15,3,) -> 4015.812 | E8: =IF(D7=$A$2,D5*C8,$A$11) -> 4015.812 | G8: Seguro Roubo (0,014%) com iof | I8: =($D$25*0.01%)*7.38%+($D$25*0.01%) -> 36.439142 | L8: Desp. Frota | N8: 1301293 | P8: Avarias S/ | S8: 600078
G9: Custo Indenizações | L9: Diárias | N9: -306752 | P9: FATURAMENTO | S9: =S8/S7 -> 0.0070074117
B10: IMPOSTOS | G10: Custo Ajudantes extras/entregas | L10: Lavação | N10: -54194
B11: TRIBUTO | C11: ALÍQUOTA | D11: VALOR | G11: Comissão Comercial/Freelancer | L11: Sinistro | N11: -37032
B12: ICMS | D12: =VLOOKUP(D3,FONTES!B5:I15,3,) -> 4015.812 | F12: =N27 -> 0.20906161 | G12: RATEIO DESP. ADMINIST./apoio op | I12: ='CUSTO NOVA'!X83 -> 1793.2052 | J12: =I12/D5 -> 0.053584336 | L12: Reboque | N12: -16900
B13: INSS DESON. 1,2 | F13: =N15 -> 0.19042701 | G13: RATEIO DESP. CLT operacional | I13: ='CUSTO NOVA'!Z83 -> 1633.3687 | J13: =I13/D5 -> 0.048808124 | L13: Gerenciamento de Risco | N13: -2055
B14: ISS | C14: 0 | D14: =IF(D5="","",(D5*C14)) -> 0 | G14: TOTAL CUSTOS | I14: =SUM(I5:I13) -> 26358.482 | J14: =SUM(J12:J13) -> 0.10239246 | L14: TOTAL | N14: =SUM(N8:N13) -> 884360
B15: PIS | C15: 0.052 | D15: =D5*C15 -> 1740.1852 | L15: RATEIO | N15: =(N7+N14)/S3 -> 0.19042701
B16: COFINS | G16: APURAÇÃO DO RESULTADO
B17: IRPJ | G17: VALOR BRUTO | I17: =D5 -> 33465.1
B18: CSLL | G18: ( - ) IMPOSTOS | I18: =D19*-1 -> -5755.9972
B19: TOTAL TRIBITOS | D19: =SUM(D12:D18) -> 5755.9972 | G19: ( - ) CUSTOS | I19: =I14*-1 -> -26358.482
L20: CUSTOS
B21: VALOR RECEITA LIQUIDA: | D21: =D5-D19 -> 27709.103 | L21: Despesa Adminstrativa | N21: 15734290
G22: VALOR LIQUIDO | I22: =SUM(I17:I21) -> 1350.6203 | L22: Boletos | N22: 76586
B23: INFORMAÇÕES EXTRAS | G23: % | I23: =I22*100%/I17 -> 0.04035907 | L23: Target | N23: 12917
B24: Tonelada | D24: =VLOOKUP(D3,FONTES!B5:I15,4,) -> 13761.699 | L24: Multa Processo RJ | N24: -306546.52
B25: Valor de NF | D25: =VLOOKUP(D3,FONTES!B5:I15,7,) -> 339347.57 | G25: QTD CTRC | H25: 82 | I25: =SUM(I26:I27) -> 1 | L25: Manutenções/Instalações Predial/Balanço Patrimonial | N25: -788861
B26: Redespacho | D26: =VLOOKUP(D3,FONTES!B5:I15,6,) -> 8055.45 | E26: =D26/D5 -> 0.24071197 | G26: Bases | H26: 16 | I26: =H26/H25 -> 0.19512195 | L26: TOTAL | N26: =SUM(N21:N25) -> 14728385
G27: Redespachos | H27: 66 | I27: =H27/H25 -> 0.80487805 | L27: RATEIO | N27: =N26/S3 -> 0.20906161
B28: Fat. cte Redespacho | D28: 21962.954 | E28: =D26/D28 -> 0.36677443
B29: Excluído por estar inclusa no Rateio Desp. ADM/OP
B30: Tonelada

Sheet FONTES
B5: COMPETENCIA | C5: TOTAL CTRC | D5: IMPOSTOS | E5: TONELADA | F5: FRETE | G5: REDESPACHO | H5: VALOR MERCADORIA | I5: TOTAL
B6: jan | C6: ='CUSTO NOVA'!I83 -> 82 | D6: ='CUSTO NOVA'!AF83 -> 4015.812 | E6: ='CUSTO NOVA'!L83 -> 13761.699 | F6: ='CUSTO NOVA'!M83 -> 33465.1 | G6: ='CUSTO NOVA'!T83 -> 8055.45 | H6: ='CUSTO NOVA'!J83 -> 339347.57 | I6: ='CUSTO NOVA'!V83 -> 22859.03
B7: feb
B8: mar
B9: apr
B10: may
B11: jun
B12: jul
B13: aug
B14: sep
B15: Total Geral | C15: =SUM(C6:C14) -> 82 | D15: =SUM(D6:D14) -> 4015.812 | E15: =SUM(E6:E14) -> 13761.699 | F15: =SUM(F6:F14) -> 33465.1 | G15: =SUM(G6:G14) -> 8055.45 | H15: =SUM(H6:H14) -> 339347.57 | I15: =SUM(I6:I14) -> 22859.03

Sheet RESULTADO REDESPACHO

Sheet BASE DADOS
A1: 1 | B1: Serie/Numero CTRC | C1: Tipo do Documento | D1: Praca Expedidora | E1: Unidade Emissora | F1: Data de Emissao | G1: Placa de Coleta | H1: Chave CT-e | I1: CNPJ Remetente | J1: Cliente Remetente | K1: Endereco do Remetente | L1: Bairro do Remetente | M1: Setor de Coleta | N1: Cidade do Remetente | O1: UF do Remetente | P1: CEP do Remetente | Q1: CNPJ Expedidor | R1: Cliente Expedidor | S1: Cidade do Expedidor | T1: UF do Expedidor | U1: CNPJ Pagador | V1: Cliente Pagador | W1: Endereco do Pagador | X1: Bairro do Pagador | Y1: Cidade do Pagador | Z1: UF do Pagador | AA1: Fone do Pagador | AB1: Segmento do Pagador | AC1: CNPJ Destinatario | AD1: Cliente Destinatario | AE1: Setor de Destino | AF1: Praca de Destino | AG1: Cidade do Destinatario | AH1: UF do Destinatario | AI1: CNPJ Recebedor | AJ1: Cliente Recebedor | AK1: Cidade de Entrega | AL1: UF de Entrega | AM1: Unidade Receptora | AN1: Numero da Nota Fiscal | AO1: Peso Real em Kg | AP1: Cubagem em m3 | AQ1: Quantidade de Volumes | AR1: Quantidade de Pares | AS1: Tipo do Frete | AT1: Tipo de Baixa | AU1: Data da Liquidacao | AV1: Valor Liquidado | AW1: Mercadoria | AX1: Especie | AY1: Valor da Mercadoria | AZ1: Tipo de Calculo | BA1: Tabela de Calculo | BB1: Valor do Frete | BC1: Valor do Frete sem ICMS | BD1: Base Calculo ICMS/ISS | BE1: Valor do ICMS | BF1: Aliquota | BG1: Valor do ISS | BH1: Peso Calculado em Kg | BI1: Frete Peso | BJ1: Frete Valor | BK1: Despacho | BL1: CAT | BM1: ITR | BN1: GRIS | BO1: Pedagio | BP1: TAS | BQ1: TDA | BR1: Suframa | BS1: Dev Canhoto NF | BT1: Reembolso | BU1: Outros | BV1: Coleta | BW1: TDC | BX1: TDE | BY1: TAR | BZ1: TRT | CA1: POS | CB1: Praca Comercial Origem | CC1: Praca Comercial Destino | CD1: Frete NTC | CE1: Frete Entrega | CF1: Separacao | CG1: Capatazia | CH1: Veiculo Dedicado | CI1: Paletizacao | CJ1: CO2 | CK1: RDC | CL1: CTRC Origem | CM1: CTe Origem | CN1: Valor do Frete do CTRC Origem | CO1: TDC CTRC Origem | CP1: TDE CTRC Origem | CQ1: TAR CTRC Origem | CR1: TRT CTRC Origem | CS1: TDA CTRC Origem | CT1: Valor do ICMS origem | CU1: Valor da Comissao de Expedicao | CV1: Rel de Comissao de Expedicao | CW1: Valor da Comissao Exp Creditada | CX1: Fatura do Subcon Exp Conferida Opcao 607 | CY1: Valor da Comissao de Recepcao | CZ1: Rel de Comissao de Recepcao | DA1: Valor da Comissao Rec Creditada | DB1: Fatura do Subcon Rec Conferida Opcao 607 | DE1: Adicional de Frete | DF1: ABC Pagador | DG1: UF origem da prestacao | DH1: Cidade origem da prestacao | DI1: IE cliente remetente | DJ1: Fone Remetente | DK1: Agendamento | DL1: Unidade Responsavel Pagador | DM1: Imposto Repassado
A2: 2 | B2: JOI025273-5 | C2: NORMAL | D2: JOIR | E2: JOI | F2: 46237 | G2: MMM1H28 | H2: 42260803098929000789570010000251101003655624 | I2: 61105060000163 | J2: BRASCOLA LTDA - | K2: RUA DONA FRANCISCA 8300 BLOCO D | L2: ZONA INDUSTRIAL | M2: 892 | N2: JOINVILLE | O2: SC | P2: 89219-600 | Q2: 61105060000163 | R2: BRASCOLA LTDA - | S2: JOINVILLE | T2: SC | U2: 61105060000163 | V2: BRASCOLA LTDA - | W2: RUA DONA FRANCISCA 8300 BLOCO D | X2: ZONA INDUSTRIAL | Y2: JOINVILLE | Z2: SC | AA2: (47 ) 32052727 | AC2: 18245738000184 | AD2: CACIFE TINTAS LTDA | AE2: 4 ROTA POUSO ALEGRE | AF2: DCCR | AG2: POUSO ALEGRE | AH2: MG | AI2: 18245738000184 | AJ2: CACIFE TINTAS LTDA | AK2: POUSO ALEGRE | AL2: MG | AM2: DCC | AN2: 000330234 | AO2: 55.36 | AP2: 0.0001 | AQ2: 10 | AR2: 0 | AS2: CP | AT2: LIQUIDADO | AU2: 46262 | AV2: 247.68 | AW2: 001-DIVERSOS | AX2: 001-DIVERSOS | AY2: 1536.74 | AZ2: COMBINADA | BA2: CO3809046 | BB2: 247.68 | BC2: 217.96 | BD2: 247.68 | BE2: 29.72 | BF2: 0.12 | BG2: 0 | BH2: 55.36 | BI2: 181.6 | BJ2: 0 | BK2: 18 | BL2: 0 | BM2: 0 | BN2: 3.25 | BO2: 5.5 | BP2: 4.23 | BQ2: 0 | BR2: 0 | BS2: 0 | BT2: 0 | BU2: 0 | BV2: 0 | BW2: 0 | BX2: 0 | BY2: 0 | BZ2: 0 | CA2: 5.38 | CB2: RSCP | CC2: ALTP | CD2: 373.35 | CE2: 0 | CF2: 0 | CG2: 0 | CH2: 0 | CI2: 0 | CJ2: 0 | CK2: 0 | CN2: 0 | CO2: 0 | CP2: 0 | CQ2: 0 | CR2: 0 | CS2: 0 | CT2: 0 | CU2: 49.54 | CV2: FATURA: 12310 | CW2: 49.54 | CX2: 012310 | CY2: 86.69 | CZ2: FATURA: 143 | DA2: 86.69 | DB2: 000143 | DE2: 0 | DF2: A. | DG2: SC | DH2: JOINVILLE | DI2: 252895738 | DJ2: (47 ) 32052727 | DK2: 0 | DL2: JOI | DM2: 29.72
A3: 2 | B3: JOI025274-3 | C3: NORMAL | D3: JOIR | E3: JOI | F3: 46237 | G3: MMM1H28 | H3: 42260803098929000789570010000251111003655630 | I3: 61105060000163 | J3: BRASCOLA LTDA - | K3: RUA DONA FRANCISCA 8300 BLOCO D | L3: ZONA INDUSTRIAL | M3: 892 | N3: JOINVILLE | O3: SC | P3: 89219-600 | Q3: 61105060000163 | R3: BRASCOLA LTDA - | S3: JOINVILLE | T3: SC | U3: 61105060000163 | V3: BRASCOLA LTDA - | W3: RUA DONA FRANCISCA 8300 BLOCO D | X3: ZONA INDUSTRIAL | Y3: JOINVILLE | Z3: SC | AA3: (47 ) 32052727 | AC3: 22429872000102 | AD3: LUMINOSOS E TOLDOS ITAJUBA LTDA ME | AE3: 3 ROTA ITAJUBA | AF3: DCCR | AG3: ITAJUBA | AH3: MG | AI3: 22429872000102 | AJ3: LUMINOSOS E TOLDOS ITAJUBA LTDA ME | AK3: ITAJUBA | AL3: MG | AM3: DCC | AN3: 000330250 | AO3: 44.036 | AP3: 0.0001 | AQ3: 13 | AR3: 0 | AS3: CP | AT3: LIQUIDADO | AU3: 46262 | AV3: 204.4 | AW3: 001-DIVERSOS | AX3: 001-DIVERSOS | AY3: 1596.25 | AZ3: COMBINADA | BA3: CO3809036 | BB3: 204.4 | BC3: 179.87 | BD3: 204.4 | BE3: 24.53 | BF3: 0.12 | BG3: 0 | BH3: 44.036 | BI3: 143.3 | BJ3: 0 | BK3: 18 | BL3: 0 | BM3: 0 | BN3: 3.25 | BO3: 5.5 | BP3: 4.23 | BQ3: 0 | BR3: 0 | BS3: 0 | BT3: 0 | BU3: 0 | BV3: 0 | BW3: 0 | BX3: 0 | BY3: 0 | BZ3: 0 | CA3: 5.59 | CB3: RSCP | CC3: ALTR | CD3: 373.95 | CE3: 0 | CF3: 0 | CG3: 0 | CH3: 0 | CI3: 0 | CJ3: 0 | CK3: 0 | CN3: 0 | CO3: 0 | CP3: 0 | CQ3: 0 | CR3: 0 | CS3: 0 | CT3: 0 | CU3: 40.88 | CV3: FATURA: 12310 | CW3: 40.88 | CX3: 012310 | CY3: 71.54 | CZ3: FATURA: 143 | DA3: 71.54 | DB3: 000143 | DE3: 0 | DF3: A. | DG3: SC | DH3: JOINVILLE | DI3: 252895738 | DJ3: (47 ) 32052727 | DK3: 0 | DL3: JOI | DM3: 24.53
A4: 2 | B4: JOI025275-1 | C4: NORMAL | D4: JOIR | E4: JOI | F4: 46237 | G4: MMM1H28 | H4: 42260803098929000789570010000251121003655645 | I4: 61105060000163 | J4: BRASCOLA LTDA - | K4: RUA DONA FRANCISCA 8300 BLOCO D | L4: ZONA INDUSTRIAL | M4: 892 | N4: JOINVILLE | O4: SC | P4: 89219-600 | Q4: 61105060000163 | R4: BRASCOLA LTDA - | S4: JOINVILLE | T4: SC | U4: 61105060000163 | V4: BRASCOLA LTDA - | W4: RUA DONA FRANCISCA 8300 BLOCO D | X4: ZONA INDUSTRIAL | Y4: JOINVILLE | Z4: SC | AA4: (47 ) 32052727 | AC4: 27743915000143 | AD4: ADILIA FERNANDA PINTO | AE4: 386 | AF4: STJP | AG4: PARACATU | AH4: MG | AI4: 27743915000143 | AJ4: ADILIA FERNANDA PINTO | AK4: PARACATU | AL4: MG | AM4: STJ | AN4: 000330273 | AO4: 64.212 | AP4: 0.0001 | AQ4: 18 | AR4: 0 | AS4: CP | AT4: LIQUIDADO | AU4: 46262 | AV4: 251.33 | AW4: 001-DIVERSOS | AX4: 001-DIVERSOS | AY4: 2369.18 | AZ4: COMBINADA | BA4: CO3809048 | BB4: 251.33 | BC4: 221.17 | BD4: 251.33 | BE4: 30.16 | BF4: 0.12 | BG4: 0 | BH4: 64.212 | BI4: 181.6 | BJ4: 0 | BK4: 18 | BL4: 0 | BM4: 0 | BN4: 3.55 | BO4: 5.5 | BP4: 4.23 | BQ4: 0 | BR4: 0 | BS4: 0 | BT4: 0 | BU4: 0 | BV4: 0 | BW4: 0 | BX4: 0 | BY4: 0 | BZ4: 0 | CA4: 8.29 | CB4: RSCP | CC4: PANI | CD4: 381.67 | CE4: 0 | CF4: 0 | CG4: 0 | CH4: 0 | CI4: 0 | CJ4: 0 | CK4: 0 | CN4: 0 | CO4: 0 | CP4: 0 | CQ4: 0 | CR4: 0 | CS4: 0 | CT4: 0 | CU4: 50.27 | CV4: FATURA: 12310 | CW4: 50.27 | CX4: 012310 | CY4: 51 | CZ4: FATURA: 64592 | DA4: 51 | DB4: 064592 | DE4: 0 | DF4: A. | DG4: SC | DH4: JOINVILLE | DI4: 252895738 | DJ4: (47 ) 32052727 | DK4: 0 | DL4: JOI | DM4: 30.16
A5: 2 | B5: JOI025276-0 | C5: NORMAL | D5: JOIR | E5: JOI | F5: 46237 | G5: MMM1H28 | H5: 42260803098929000789570010000251131003655650 | I5: 61105060000163 | J5: BRASCOLA LTDA - | K5: RUA DONA FRANCISCA 8300 BLOCO D | L5: ZONA INDUSTRIAL | M5: 892 | N5: JOINVILLE | O5: SC | P5: 89219-600 | Q5: 61105060000163 | R5: BRASCOLA LTDA - | S5: JOINVILLE | T5: SC | U5: 61105060000163 | V5: BRASCOLA LTDA - | W5: RUA DONA FRANCISCA 8300 BLOCO D | X5: ZONA INDUSTRIAL | Y5: JOINVILLE | Z5: SC | AA5: (47 ) 32052727 | AC5: 17732396000164 | AD5: DAVI ARRUDA DAS DORES ME | AE5: 010 RIBEIRAO DAS NEVES | AF5: BHZP | AG5: RIBEIRAO DAS NEVES | AH5: MG | AI5: 17732396000164 | AJ5: DAVI ARRUDA DAS DORES ME | AK5: RIBEIRAO DAS NEVES | AL5: MG | AM5: BHZ | AN5: 000330178 | AO5: 205.52 | AP5: 0.0001 | AQ5: 28 | AR5: 0 | AS5: CP | AT5: LIQUIDADO | AU5: 46262 | AV5: 394 | AW5: 001-DIVERSOS | AX5: 001-DIVERSOS | AY5: 4577.16 | AZ5: COMBINADA | BA5: CO3809017 | BB5: 394 | BC5: 346.72 | BD5: 394 | BE5: 47.28 | BF5: 0.12 | BG5: 0 | BH5: 205.52 | BI5: 285.1 | BJ5: 0 | BK5: 18 | BL5: 0 | BM5: 0 | BN5: 6.87 | BO5: 16.5 | BP5: 4.23 | BQ5: 0 | BR5: 0 | BS5: 0 | BT5: 0 | BU5: 0 | BV5: 0 | BW5: 0 | BX5: 0 | BY5: 0 | BZ5: 0 | CA5: 16.02 | CB5: RSCP | CC5: BHZP | CD5: 423.29 | CE5: 0 | CF5: 0 | CG5: 0 | CH5: 0 | CI5: 0 | CJ5: 0 | CK5: 0 | CN5: 0 | CO5: 0 | CP5: 0 | CQ5: 0 | CR5: 0 | CS5: 0 | CT5: 0 | CU5: 78.8 | CV5: FATURA: 12310 | CW5: 78.8 | CX5: 012310 | CY5: 28.77 | CZ5: MAPA: 161 | DA5: 0 | DE5: 0 | DF5: A. | DG5: SC | DH5: JOINVILLE | DI5: 252895738 | DJ5: (47 ) 32052727 | DK5: 0 | DL5: JOI | DM5: 47.28
A6: 2 | B6: JOI025277-8 | C6: NORMAL | D6: JOIR | E6: JOI | F6: 46237 | G6: MMM1H28 | H6: 42260803098929000789570010000251061003655575 | I6: 61105060000163 | J6: BRASCOLA LTDA - | K6: RUA DONA FRANCISCA 8300 BLOCO D | L6: ZONA INDUSTRIAL | M6: 892 | N6: JOINVILLE | O6: SC | P6: 89219-600 | Q6: 61105060000163 | R6: BRASCOLA LTDA - | S6: JOINVILLE | T6: SC | U6: 61105060000163 | V6: BRASCOLA LTDA - | W6: RUA DONA FRANCISCA 8300 BLOCO D | X6: ZONA INDUSTRIAL | Y6: JOINVILLE | Z6: SC | AA6: (47 ) 32052727 | AC6: 21980768000149 | AD6: AUTOLATAS ACESSORIOS LTDA EIRE | AE6: 001 SETE LAGOAS | AF6: SETP | AG6: SETE LAGOAS | AH6: MG | AI6: 21980768000149 | AJ6: AUTOLATAS ACESSORIOS LTDA EIRE | AK6: SETE LAGOAS | AL6: MG | AM6: SET | AN6: 000330177 | AO6: 65.852 | AP6: 0.0001 | AQ6: 9 | AR6: 0 | AS6: CP | AT6: LIQUIDADO | AU6: 46262 | AV6: 192.06 | AW6: 001-DIVERSOS | AX6: 001-DIVERSOS | AY6: 1699.8 | AZ6: 1700.8 | BA6: CO3809016 | BB6: 192.06 | BC6: 169.01 | BD6: 192.06 | BE6: 23.05 | BF6: 0.12 | BG6: 0 | BH6: 65.852 | BI6: 132.08 | BJ6: 0 | BK6: 18 | BL6: 0 | BM6: 0 | BN6: 3.25 | BO6: 5.5 | BP6: 4.23 | BQ6: 0 | BR6: 0 | BS6: 0 | BT6: 0 | BU6: 0 | BV6: 0 | BW6: 0 | BX6: 0 | BY6: 0 | BZ6: 0 | CA6: 5.95 | CB6: RSCP | CC6: SETP | CD6: 374.97 | CE6: 0 | CF6: 0 | CG6: 0 | CH6: 0 | CI6: 0 | CJ6: 0 | CK6: 0 | CN6: 0 | CO6: 0 | CP6: 0 | CQ6: 0 | CR6: 0 | CS6: 0 | CT6: 0 | CU6: 38.41 | CV6: FATURA: 12310 | CW6: 38.41 | CX6: 012310 | CY6: 12 | CZ6: MAPA: 161 | DA6: 0 | DE6: 0 | DF6: A. | DG6: SC | DH6: JOINVILLE | DI6: 252895738 | DJ6: (47 ) 32052727 | DK6: 0 | DL6: JOI | DM6: 23.05
A7: 2 | B7: JOI025278-6 | C7: NORMAL | D7: JOIR | E7: JOI | F7: 46237 | G7: MMM1H28 | H7: 42260803098929000789570010000251041003655538 | I7: 61105060000163 | J7: BRASCOLA LTDA - | K7: RUA DONA FRANCISCA 8300 BLOCO D | L7: ZONA INDUSTRIAL | M7: 892 | N7: JOINVILLE | O7: SC | P7: 89219-600 | Q7: 61105060000163 | R7: BRASCOLA LTDA - | S7: JOINVILLE | T7: SC | U7: 61105060000163 | V7: BRASCOLA LTDA - | W7: RUA DONA FRANCISCA 8300 BLOCO D | X7: ZONA INDUSTRIAL | Y7: JOINVILLE | Z7: SC | AA7: (47 ) 32052727 | AC7: 64220981000165 | AD7: MUNDIAL TINTAS E FERRAMENTAS LTDA | AE7: 12 ROTA CAMPOS GERAIS | AF7: DCCR | AG7: TRES PONTAS | AH7: MG | AI7: 64220981000165 | AJ7: MUNDIAL TINTAS E FERRAMENTAS LTDA | AK7: TRES PONTAS | AL7: MG | AM7: DCC | AN7: 000330175 | AO7: 107.628 | AP7: 0.0001 | AQ7: 21 | AR7: 0 | AS7: CP | AT7: LIQUIDADO | AU7: 46262 | AV7: 288.84 | AW7: 001-DIVERSOS | AX7: 001-DIVERSOS | AY7: 2951.4 | AZ7: COMBINADA | BA7: CO3809037 | BB7: 288.84 | BC7: 254.18 | BD7: 288.84 | BE7: 34.66 | BF7: 0.12 | BG7: 0 | BH7: 107.628 | BI7: 206.19 | BJ7: 0 | BK7: 18 | BL7: 0 | BM7: 0 | BN7: 4.43 | BO7: 11 | BP7: 4.23 | BQ7: 0 | BR7: 0 | BS7: 0 | BT7: 0 | BU7: 0 | BV7: 0 | BW7: 0 | BX7: 0 | BY7: 0 | BZ7: 0 | CA7: 10.33 | CB7: RSCP | CC7: ALTI | CD7: 388.38 | CE7: 0 | CF7: 0 | CG7: 0 | CH7: 0 | CI7: 0 | CJ7: 0 | CK7: 0 | CN7: 0 | CO7: 0 | CP7: 0 | CQ7: 0 | CR7: 0 | CS7: 0 | CT7: 0 | CU7: 57.77 | CV7: FATURA: 12310 | CW7: 57.77 | CX7: 012310 | CY7: 101.09 | CZ7: FATURA: 143 | DA7: 101.09 | DB7: 000143 | DE7: 0 | DF7: A. | DG7: SC | DH7: JOINVILLE | DI7: 252895738 | DJ7: (47 ) 32052727 | DK7: 0 | DL7: JOI | DM7: 34.66
A8: 2 | B8: JOI025279-4 | C8: NORMAL | D8: JOIR | E8: JOI | F8: 46237 | G8: MMM1H28 | H8: 42260803098929000789570010000251071003655599 | I8: 61105060000163 | J8: BRASCOLA LTDA - | K8: RUA DONA FRANCISCA 8300 BLOCO D | L8: ZONA INDUSTRIAL | M8: 892 | N8: JOINVILLE | O8: SC | P8: 89219-600 | Q8: 61105060000163 | R8: BRASCOLA LTDA - | S8: JOINVILLE | T8: SC | U8: 61105060000163 | V8: BRASCOLA LTDA - | W8: RUA DONA FRANCISCA 8300 BLOCO D | X8: ZONA INDUSTRIAL | Y8: JOINVILLE | Z8: SC | AA8: (47 ) 32052727 | AC8: 26600777000180 | AD8: PAULO ROBERTO REZENDE | AE8: 1 ROTA VARGINHA | AF8: DCCR | AG8: VARGINHA | AH8: MG | AI8: 26600777000180 | AJ8: PAULO ROBERTO REZENDE | AK8: VARGINHA | AL8: MG | AM8: DCC | AN8: 000330170 | AO8: 327.948 | AP8: 0.0001 | AQ8: 48 | AR8: 0 | AS8: CP | AT8: LIQUIDADO | AU8: 46262 | AV8: 632.51 | AW8: 001-DIVERSOS | AX8: 001-DIVERSOS | AY8: 7938.11 | AZ8: COMBINADA | BA8: CO3809036 | BB8: 632.51 | BC8: 556.61 | BD8: 632.51 | BE8: 75.9 | BF8: 0.12 | BG8: 0 | BH8: 327.948 | BI8: 472.69 | BJ8: 0 | BK8: 18 | BL8: 0 | BM8: 0 | BN8: 11.91 | BO8: 22 | BP8: 4.23 | BQ8: 0 | BR8: 0 | BS8: 0 | BT8: 0 | BU8: 0 | BV8: 0 | BW8: 0 | BX8: 0 | BY8: 0 | BZ8: 0 | CA8: 27.78 | CB8: RSCP | CC8: ALTR | CD8: 773.05 | CE8: 0 | CF8: 0 | CG8: 0 | CH8: 0 | CI8: 0 | CJ8: 0 | CK8: 0 | CN8: 0 | CO8: 0 | CP8: 0 | CQ8: 0 | CR8: 0 | CS8: 0 | CT8: 0 | CU8: 126.5 | CV8: FATURA: 12310 | CW8: 126.5 | CX8: 012310 | CY8: 221.38 | CZ8: FATURA: 143 | DA8: 221.38 | DB8: 000143 | DE8: 0 | DF8: A. | DG8: SC | DH8: JOINVILLE | DI8: 252895738 | DJ8: (47 ) 32052727 | DK8: 0 | DL8: JOI | DM8: 75.9
A9: 2 | B9: JOI025280-8 | C9: NORMAL | D9: JOIR | E9: JOI | F9: 46237 | G9: MMM1H28 | H9: 42260803098929000789570010000251051003655551 | I9: 61105060000163 | J9: BRASCOLA LTDA - | K9: RUA DONA FRANCISCA 8300 BLOCO D | L9: ZONA INDUSTRIAL | M9: 892 | N9: JOINVILLE | O9: SC | P9: 89219-600 | Q9: 61105060000163 | R9: BRASCOLA LTDA - | S9: JOINVILLE | T9: SC | U9: 61105060000163 | V9: BRASCOLA LTDA - | W9: RUA DONA FRANCISCA 8300 BLOCO D | X9: ZONA INDUSTRIAL | Y9: JOINVILLE | Z9: SC | AA9: (47 ) 32052727 | AC9: 07695443000193 | AD9: PRATA FERRO E ACO LTDA | AE9: 355 | AF9: DDBP | AG9: DIVINOPOLIS | AH9: MG | AI9: 07695443000193 | AJ9: PRATA FERRO E ACO LTDA | AK9: DIVINOPOLIS | AL9: MG | AM9: DDB | AN9: 000330186 | AO9: 1 | AP9: 0.0001 | AQ9: 1 | AR9: 0 | AS9: CP | AT9: LIQUIDADO | AU9: 46262 | AV9: 178.75 | AW9: 001-DIVERSOS | AX9: 001-DIVERSOS | AY9: 59.58 | AZ9: COMBINADA | BA9: CO3809055 | BB9: 178.75 | BC9: 157.3 | BD9: 178.75 | BE9: 21.45 | BF9: 0.12 | BG9: 0 | BH9: 1 | BI9: 126.11 | BJ9: 0 | BK9: 18 | BL9: 0 | BM9: 0 | BN9: 3.25 | BO9: 5.5 | BP9: 4.23 | BQ9: 0 | BR9: 0 | BS9: 0 | BT9: 0 | BU9: 0 | BV9: 0 | BW9: 0 | BX9: 0 | BY9: 0 | BZ9: 0 | CA9: 0.21 | CB9: RSCP | CC9: RWNI | CD9: 358.58 | CE9: 0 | CF9: 0 | CG9: 0 | CH9: 0 | CI9: 0 | CJ9: 0 | CK9: 0 | CN9: 0 | CO9: 0 | CP9: 0 | CQ9: 0 | CR9: 0 | CS9: 0 | CT9: 0 | CU9: 35.75 | CV9: FATURA: 12310 | CW9: 35.75 | CX9: 012310 | CY9: 54 | CZ9: MAPA: 0 | DA9: =CY9 -> 54 | DE9: 0 | DF9: A. | DG9: SC | DH9: JOINVILLE | DI9: 252895738 | DJ9: (47 ) 32052727 | DK9: 0 | DL9: JOI | DM9: 21.45
A10: 2 | B10: JOI025281-6 | C10: NORMAL | D10: JOIR | E10: JOI | F10: 46237 | G10: MMM1H28 | H10: 42260803098929000789570010000251081003655600 | I10: 61105060000163 | J10: BRASCOLA LTDA - | K10: RUA DONA FRANCISCA 8300 BLOCO D | L10: ZONA INDUSTRIAL | M10: 892 | N10: JOINVILLE | O10: SC | P10: 89219-600 | Q10: 61105060000163 | R10: BRASCOLA LTDA - | S10: JOINVILLE | T10: SC | U10: 61105060000163 | V10: BRASCOLA LTDA - | W10: RUA DONA FRANCISCA 8300 BLOCO D | X10: ZONA INDUSTRIAL | Y10: JOINVILLE | Z10: SC | AA10: (47 ) 32052727 | AC10: 06249968000132 | AD10: WME INDUSTRIA E COMERCIO DE PERFILADOS LTDA | AE10: 351 | AF10: GVRP | AG10: TIMOTEO | AH10: MG | AI10: 06249968000132 | AJ10: WME INDUSTRIA E COMERCIO DE PERFILADOS LTDA | AK10: TIMOTEO | AL10: MG | AM10: GVR | AN10: 000330185 | AO10: 1 | AP10: 0.0001 | AQ10: 1 | AR10: 0 | AS10: CP | AT10: LIQUIDADO | AU10: 46262 | AV10: 178.75 | AW10: 001-DIVERSOS | AX10: 001-DIVERSOS | AY10: 59.58 | AZ10: COMBINADA | BA10: CO3809055 | BB10: 178.75 | BC10: 157.3 | BD10: 178.75 | BE10: 21.45 | BF10: 0.12 | BG10: 0 | BH10: 1 | BI10: 126.11 | BJ10: 0 | BK10: 18 | BL10: 0 | BM10: 0 | BN10: 3.25 | BO10: 5.5 | BP10: 4.23 | BQ10: 0 | BR10: 0 | BS10: 0 | BT10: 0 | BU10: 0 | BV10: 0 | BW10: 0 | BX10: 0 | BY10: 0 | BZ10: 0 | CA10: 0.21 | CB10: RSCP | CC10: RWNI | CD10: 358.58 | CE10: 0 | CF10: 0 | CG10: 0 | CH10: 0 | CI10: 0 | CJ10: 0 | CK10: 0 | CN10: 0 | CO10: 0 | CP10: 0 | CQ10: 0 | CR10: 0 | CS10: 0 | CT10: 0 | CU10: 35.75 | CV10: FATURA: 12310 | CW10: 35.75 | CX10: 012310 | CY10: 67.06 | CZ10: FATURA: 12223 | DA10: 67.06 | DB10: 012223 | DE10: 0 | DF10: A. | DG10: SC | DH10: JOINVILLE | DI10: 252895738 | DJ10: (47 ) 32052727 | DK10: 0 | DL10: JOI | DM10: 21.45
A11: 2 | B11: JOI025282-4 | C11: NORMAL | D11: JOIR | E11: JOI | F11: 46237 | G11: MMM1H28 | H11: 42260803098929000789570010000251091003655615 | I11: 61105060000163 | J11: BRASCOLA LTDA - | K11: RUA DONA FRANCISCA 8300 BLOCO D | L11: ZONA INDUSTRIAL | M11: 892 | N11: JOINVILLE | O11: SC | P11: 89219-600 | Q11: 61105060000163 | R11: BRASCOLA LTDA - | S11: JOINVILLE | T11: SC | U11: 61105060000163 | V11: BRASCOLA LTDA - | W11: RUA DONA FRANCISCA 8300 BLOCO D | X11: ZONA INDUSTRIAL | Y11: JOINVILLE | Z11: SC | AA11: (47 ) 32052727 | AC11: 05290889000102 | AD11: CENTER TINTAS DE PARACATU LTDA - EPP | AE11: 386 | AF11: STJP | AG11: PARACATU | AH11: MG | AI11: 05290889000102 | AJ11: CENTER TINTAS DE PARACATU LTDA - EPP | AK11: PARACATU | AL11: MG | AM11: STJ | AN11: 000330223 | AO11: 65.694 | AP11: 0.0001 | AQ11: 11 | AR11: 0 | AS11: CP | AT11: LIQUIDADO | AU11: 46262 | AV11: 248.9 | AW11: 001-DIVERSOS | AX11: 001-DIVERSOS | AY11: 1842.97 | AZ11: COMBINADA | BA11: CO3809048 | BB11: 248.9 | BC11: 219.03 | BD11: 248.9 | BE11: 29.87 | BF11: 0.12 | BG11: 0 | BH11: 65.694 | BI11: 181.6 | BJ11: 0 | BK11: 18 | BL11: 0 | BM11: 0 | BN11: 3.25 | BO11: 5.5 | BP11: 4.23 | BQ11: 0 | BR11: 0 | BS11: 0 | BT11: 0 | BU11: 0 | BV11: 0 | BW11: 0 | BX11: 0 | BY11: 0 | BZ11: 0 | CA11: 6.45 | CB11: RSCP | CC11: PANI | CD11: 376.44 | CE11: 0 | CF11: 0 | CG11: 0 | CH11: 0 | CI11: 0 | CJ11: 0 | CK11: 0 | CN11: 0 | CO11: 0 | CP11: 0 | CQ11: 0 | CR11: 0 | CS11: 0 | CT11: 0 | CU11: 49.78 | CV11: FATURA: 12310 | CW11: 49.78 | CX11: 012310 | CY11: 51 | CZ11: FATURA: 64592 | DA11: 51 | DB11: 064592 | DE11: 0 | DF11: A. | DG11: SC | DH11: JOINVILLE | DI11: 252895738 | DJ11: (47 ) 32052727 | DK11: 0 | DL11: JOI | DM11: 29.87
A12: 2 | B12: JOI025355-3 | C12: NORMAL | D12: JOIR | E12: JOI | F12: 46239 | G12: MMM1H28 | H12: 42260803098929000789570010000251851003666481 | I12: 61105060000163 | J12: BRASCOLA LTDA - | K12: RUA DONA FRANCISCA 8300 BLOCO D | L12: ZONA INDUSTRIAL | M12: 892 | N12: JOINVILLE | O12: SC | P12: 89219-600 | Q12: 61105060000163 | R12: BRASCOLA LTDA - | S12: JOINVILLE | T12: SC | U12: 61105060000163 | V12: BRASCOLA LTDA - | W12: RUA DONA FRANCISCA 8300 BLOCO D | X12: ZONA INDUSTRIAL | Y12: JOINVILLE | Z12: SC | AA12: (47 ) 32052727 | AC12: 08853127000165 | AD12: BR FERRAGENS LTDA ME | AE12: 353 | AF12: GVRI | AG12: RIO CASCA | AH12: MG | AI12: 08853127000165 | AJ12: BR FERRAGENS LTDA ME | AK12: RIO CASCA | AL12: MG | AM12: GVR | AN12: 000330285 | AO12: 146.24 | AP12: 0.0001 | AQ12: 30 | AR12: 0 | AS12: CP | AT12: LIQUIDADO | AU12: 46262 | AV12: 332.13 | AW12: 001-DIVERSOS | AX12: 001-DIVERSOS | AY12: 4515.09 | AZ12: COMBINADA | BA12: CO3809041 | BB12: 332.13 | BC12: 292.27 | BD12: 332.13 | BE12: 39.86 | BF12: 0.12 | BG12: 0 | BH12: 146.24 | BI12: 236.47 | BJ12: 0 | BK12: 18 | BL12: 0 | BM12: 0 | BN12: 6.77 | BO12: 11 | BP12: 4.23 | BQ12: 0 | BR12: 0 | BS12: 0 | BT12: 0 | BU12: 0 | BV12: 0 | BW12: 0 | BX12: 0 | BY12: 0 | BZ12: 0 | CA12: 15.8 | CB12: RSCP | CC12: TAMI | CD12: 408.67 | CE12: 0 | CF12: 0 | CG12: 0 | CH12: 0 | CI12: 0 | CJ12: 0 | CK12: 0 | CN12: 0 | CO12: 0 | CP12: 0 | CQ12: 0 | CR12: 0 | CS12: 0 | CT12: 0 | CU12: 66.43 | CV12: FATURA: 12310 | CW12: 66.43 | CX12: 012310 | CY12: 125.25 | CZ12: FATURA: 12378 | DA12: 125.25 | DB12: 012378 | DE12: 0 | DF12: A. | DG12: SC | DH12: JOINVILLE | DI12: 252895738 | DJ12: (47 ) 32052727 | DK12: 0 | DL12: JOI | DM12: 39.86
A13: 2 | B13: JOI025356-1 | C13: NORMAL | D13: JOIR | E13: JOI | F13: 46239 | G13: MMM1H28 | H13: 42260803098929000789570010000251861003666497 | I13: 61105060000163 | J13: BRASCOLA LTDA - | K13: RUA DONA FRANCISCA 8300 BLOCO D | L13: ZONA INDUSTRIAL | M13: 892 | N13: JOINVILLE | O13: SC | P13: 89219-600 | Q13: 61105060000163 | R13: BRASCOLA LTDA - | S13: JOINVILLE | T13: SC | U13: 61105060000163 | V13: BRASCOLA LTDA - | W13: RUA DONA FRANCISCA 8300 BLOCO D | X13: ZONA INDUSTRIAL | Y13: JOINVILLE | Z13: SC | AA13: (47 ) 32052727 | AC13: 16690770000143 | AD13: POCOS ACABAMENTOS LTDA | AE13: 6 ROTA POCOS DE CALDAS | AF13: DCCR | AG13: POCOS DE CALDAS | AH13: MG | AI13: 16690770000143 | AJ13: POCOS ACABAMENTOS LTDA | AK13: POCOS DE CALDAS | AL13: MG | AM13: DCC | AN13: 000330315 | AO13: 29.08 | AP13: 0.0001 | AQ13: 7 | AR13: 0 | AS13: CP | AT13: LIQUIDADO | AU13: 46262 | AV13: 171.94 | AW13: 001-DIVERSOS | AX13: 001-DIVERSOS | AY13: 1624.49 | AZ13: COMBINADA | BA13: CO3809036 | BB13: 171.94 | BC13: 151.31 | BD13: 171.94 | BE13: 20.63 | BF13: 0.12 | BG13: 0 | BH13: 29.08 | BI13: 114.64 | BJ13: 0 | BK13: 18 | BL13: 0 | BM13: 0 | BN13: 3.25 | BO13: 5.5 | BP13: 4.23 | BQ13: 0 | BR13: 0 | BS13: 0 | BT13: 0 | BU13: 0 | BV13: 0 | BW13: 0 | BX13: 0 | BY13: 0 | BZ13: 0 | CA13: 5.69 | CB13: RSCP | CC13: ALTR | CD13: 374.27 | CE13: 0 | CF13: 0 | CG13: 0 | CH13: 0 | CI13: 0 | CJ13: 0 | CK13: 0 | CN13: 0 | CO13: 0 | CP13: 0 | CQ13: 0 | CR13: 0 | CS13: 0 | CT13: 0 | CU13: 34.39 | CV13: FATURA: 12310 | CW13: 34.39 | CX13: 012310 | CY13: 60.18 | CZ13: FATURA: 143 | DA13: 60.18 | DB13: 000143 | DE13: 0 | DF13: A. | DG13: SC | DH13: JOINVILLE | DI13: 252895738 | DJ13: (47 ) 32052727 | DK13: 0 | DL13: JOI | DM13: 20.63
A14: 2 | B14: JOI025357-0 | C14: NORMAL | D14: JOIR | E14: JOI | F14: 46239 | G14: MMM1H28 | H14: 42260803098929000789570010000251871003666508 | I14: 61105060000163 | J14: BRASCOLA LTDA - | K14: RUA DONA FRANCISCA 8300 BLOCO D | L14: ZONA INDUSTRIAL | M14: 892 | N14: JOINVILLE | O14: SC | P14: 89219-600 | Q14: 61105060000163 | R14: BRASCOLA LTDA - | S14: JOINVILLE | T14: SC | U14: 61105060000163 | V14: BRASCOLA LTDA - | W14: RUA DONA FRANCISCA 8300 BLOCO D | X14: ZONA INDUSTRIAL | Y14: JOINVILLE | Z14: SC | AA14: (47 ) 32052727 | AC14: 64382120000183 | AD14: W01356-01- ANTONIO GILBERTO TEIXEIRA ALVES JUNIOR | AE14: 394 | AF14: VEAI | AG14: JANAUBA | AH14: MG | AI14: 64382120000183 | AJ14: W01356-01- ANTONIO GILBERTO TEIXEIRA ALVES JUNIOR | AK14: JANAUBA | AL14: MG | AM14: VEA | AN14: 000330246 | AO14: 146.8 | AP14: 0.0001 | AQ14: 20 | AR14: 0 | AS14: CP | AT14: LIQUIDADO | AU14: 46262 | AV14: 361.7 | AW14: 001-DIVERSOS | AX14: 001-DIVERSOS | AY14: 3238.98 | AZ14: COMBINADA | BA14: CO3809060 | BB14: 361.7 | BC14: 318.3 | BD14: 361.7 | BE14: 43.4 | BF14: 0.12 | BG14: 0 | BH14: 146.8 | BI14: 268.87 | BJ14: 0 | BK14: 18 | BL14: 0 | BM14: 0 | BN14: 4.86 | BO14: 11 | BP14: 4.23 | BQ14: 0 | BR14: 0 | BS14: 0 | BT14: 0 | BU14: 0 | BV14: 0 | BW14: 0 | BX14: 0 | BY14: 0 | BZ14: 0 | CA14: 11.34 | CB14: RSCP | CC14: VEAI | CD14: 392.09 | CE14: 0 | CF14: 0 | CG14: 0 | CH14: 0 | CI14: 0 | CJ14: 0 | CK14: 0 | CN14: 0 | CO14: 0 | CP14: 0 | CQ14: 0 | CR14: 0 | CS14: 0 | CT14: 0 | CU14: 72.34 | CV14: FATURA: 12310 | CW14: 72.34 | CX14: 012310 | CY14: 108.51 | CZ14: MAPA: 0 | DA14: =CY14 -> 108.51 | DE14: 0 | DF14: A. | DG14: SC | DH14: JOINVILLE | DI14: 252895738 | DJ14: (47 ) 32052727 | DK14: 0 | DL14: JOI | DM14: 43.4
A15: 2 | B15: JOI025358-8 | C15: NORMAL | D15: JOIR | E15: JOI | F15: 46239 | G15: MMM1H28 | H15: 42260803098929000789570010000251881003666513 | I15: 61105060000163 | J15: BRASCOLA LTDA - | K15: RUA DONA FRANCISCA 8300 BLOCO D | L15: ZONA INDUSTRIAL | M15: 892 | N15: JOINVILLE | O15: SC | P15: 89219-600 | Q15: 61105060000163 | R15: BRASCOLA LTDA - | S15: JOINVILLE | T15: SC | U15: 61105060000163 | V15: BRASCOLA LTDA - | W15: RUA DONA FRANCISCA 8300 BLOCO D | X15: ZONA INDUSTRIAL | Y15: JOINVILLE | Z15: SC | AA15: (47 ) 32052727 | AC15: 86502002000102 | AD15: JUPEMAR AUTO PECAS LTDA | AE15: 359 | AF15: EJMP | AG15: JOAO MONLEVADE | AH15: MG | AI15: 86502002000102 | AJ15: JUPEMAR AUTO PECAS LTDA | AK15: JOAO MONLEVADE | AL15: MG | AM15: EJM | AN15: 000330237 | AO15: 449.876 | AP15: 0.0001 | AQ15: 1 | AR15: 0 | AS15: CP | AT15: LIQUIDADO | AU15: 46262 | AV15: 967.19 | AW15: 001-DIVERSOS | AX15: 001-DIVERSOS | AY15: 9522.96 | AZ15: COMBINADA | BA15: CO3809055 | BB15: 967.19 | BC15: 851.13 | BD15: 967.19 | BE15: 116.06 | BF15: 0.12 | BG15: 0 | BH15: 449.876 | BI15: 753.79 | BJ15: 0 | BK15: 18 | BL15: 0 | BM15: 0 | BN15: 14.28 | BO15: 27.5 | BP15: 4.23 | BQ15: 0 | BR15: 0 | BS15: 0 | BT15: 0 | BU15: 0 | BV15: 0 | BW15: 0 | BX15: 0 | BY15: 0 | BZ15: 0 | CA15: 33.33 | CB15: RSCP | CC15: RWNI | CD15: 1098.46 | CE15: 0 | CF15: 0 | CG15: 0 | CH15: 0 | CI15: 0 | CJ15: 0 | CK15: 0 | CN15: 0 | CO15: 0 | CP15: 0 | CQ15: 0 | CR15: 0 | CS15: 0 | CT15: 0 | CU15: 193.44 | CV15: FATURA: 12310 | CW15: 193.44 | CX15: 012310 | CY15: 386.88 | CZ15: MAPA: 161 | DA15: =CY15 -> 386.88 | DE15: 0 | DF15: A. | DG15: SC | DH15: JOINVILLE | DI15: 252895738 | DJ15: (47 ) 32052727 | DK15: 0 | DL15: JOI | DM15: 116.06
A16: 2 | B16: JOI025398-7 | C16: NORMAL | D16: JOIR | E16: JOI | F16: 46240 | G16: MMM1H28 | H16: 42260803098929000789570010000252291003675045 | I16: 61105060000163 | J16: BRASCOLA LTDA - | K16: RUA DONA FRANCISCA 8300 BLOCO D | L16: ZONA INDUSTRIAL | M16: 892 | N16: JOINVILLE | O16: SC | P16: 89219-600 | Q16: 61105060000163 | R16: BRASCOLA LTDA - | S16: JOINVILLE | T16: SC | U16: 61105060000163 | V16: BRASCOLA LTDA - | W16: RUA DONA FRANCISCA 8300 BLOCO D | X16: ZONA INDUSTRIAL | Y16: JOINVILLE | Z16: SC | AA16: (47 ) 32052727 | AC16: 10801726000187 | AD16: AVILA DISTRIBUIDORA E COMERCIO | AE16: 9 ROTA ALFENAS | AF16: DCCI | AG16: ALFENAS | AH16: MG | AI16: 10801726000187 | AJ16: AVILA DISTRIBUIDORA E COMERCIO | AK16: ALFENAS | AL16: MG | AM16: DCC | AN16: 000330385 | AO16: 70.43 | AP16: 0.0001 | AQ16: 31 | AR16: 0 | AS16: CP | AT16: LIQUIDADO | AU16: 46262 | AV16: 249.45 | AW16: 001-DIVERSOS | AX16: 001-DIVERSOS | AY16: 3084.36 | AZ16: COMBINADA | BA16: CO3809036 | BB16: 249.45 | BC16: 219.52 | BD16: 249.45 | BE16: 29.93 | BF16: 0.12 | BG16: 0 | BH16: 70.43 | BI16: 176.36 | BJ16: 0 | BK16: 18 | BL16: 0 | BM16: 0 | BN16: 4.63 | BO16: 5.5 | BP16: 4.23 | BQ16: 0 | BR16: 0 | BS16: 0 | BT16: 0 | BU16: 0 | BV16: 0 | BW16: 0 | BX16: 0 | BY16: 0 | BZ16: 0 | CA16: 10.8 | CB16: RSCP | CC16: ALTR | CD16: 390.07 | CE16: 0 | CF16: 0 | CG16: 0 | CH16: 0 | CI16: 0 | CJ16: 0 | CK16: 0 | CN16: 0 | CO16: 0 | CP16: 0 | CQ16: 0 | CR16: 0 | CS16: 0 | CT16: 0 | CU16: 49.89 | CV16: FATURA: 12310 | CW16: 49.89 | CX16: 012310 | CY16: 87.31 | CZ16: FATURA: 143 | DA16: 87.31 | DB16: 000143 | DE16: 0 | DF16: A. | DG16: SC | DH16: JOINVILLE | DI16: 252895738 | DJ16: (47 ) 32052727 | DK16: 0 | DL16: JOI | DM16: 29.93
A17: 2 | B17: JOI025399-5 | C17: NORMAL | D17: JOIR | E17: JOI | F17: 46240 | G17: MMM1H28 | H17: 42260803098929000789570010000252301003675054 | I17: 61105060000163 | J17: BRASCOLA LTDA - | K17: RUA DONA FRANCISCA 8300 BLOCO D | L17: ZONA INDUSTRIAL | M17: 892 | N17: JOINVILLE | O17: SC | P17: 89219-600 | Q17: 61105060000163 | R17: BRASCOLA LTDA - | S17: JOINVILLE | T17: SC | U17: 61105060000163 | V17: BRASCOLA LTDA - | W17: RUA DONA FRANCISCA 8300 BLOCO D | X17: ZONA INDUSTRIAL | Y17: JOINVILLE | Z17: SC | AA17: (47 ) 32052727 | AC17: 57006983000433 | AD17: FANIA COM E IND DE PECAS LTDA | AE17: 3 ROTA ITAJUBA | AF17: DCCR | AG17: ITAJUBA | AH17: MG | AI17: 57006983000433 | AJ17: FANIA COM E IND DE PECAS LTDA | AK17: ITAJUBA | AL17: MG | AM17: DCC | AN17: 000330394 | AO17: 64 | AP17: 0.0001 | AQ17: 4 | AR17: 0 | AS17: CP | AT17: LIQUIDADO | AU17: 46262 | AV17: 230.4 | AW17: 001-DIVERSOS | AX17: 001-DIVERSOS | AY17: 1911.24 | AZ17: COMBINADA | BA17: CO3809036 | BB17: 230.4 | BC17: 202.75 | BD17: 230.4 | BE17: 27.65 | BF17: 0.12 | BG17: 0 | BH17: 64 | BI17: 165.08 | BJ17: 0 | BK17: 18 | BL17: 0 | BM17: 0 | BN17: 3.25 | BO17: 5.5 | BP17: 4.23 | BQ17: 0 | BR17: 0 | BS17: 0 | BT17: 0 | BU17: 0 | BV17: 0 | BW17: 0 | BX17: 0 | BY17: 0 | BZ17: 0 | CA17: 6.69 | CB17: RSCP | CC17: ALTR | CD17: 377.09 | CE17: 0 | CF17: 0 | CG17: 0 | CH17: 0 | CI17: 0 | CJ17: 0 | CK17: 0 | CN17: 0 | CO17: 0 | CP17: 0 | CQ17: 0 | CR17: 0 | CS17: 0 | CT17: 0 | CU17: 46.08 | CV17: FATURA: 12310 | CW17: 46.08 | CX17: 012310 | CY17: 80.64 | CZ17: FATURA: 143 | DA17: 80.64 | DB17: 000143 | DE17: 0 | DF17: A. | DG17: SC | DH17: JOINVILLE | DI17: 252895738 | DJ17: (47 ) 32052727 | DK17: 0 | DL17: JOI | DM17: 27.65
A18: 2 | B18: JOI025400-2 | C18: NORMAL | D18: JOIR | E18: JOI | F18: 46240 | G18: MMM1H28 | H18: 42260803098929000789570010000252311003675060 | I18: 61105060000163 | J18: BRASCOLA LTDA - | K18: RUA DONA FRANCISCA 8300 BLOCO D | L18: ZONA INDUSTRIAL | M18: 892 | N18: JOINVILLE | O18: SC | P18: 89219-600 | Q18: 61105060000163 | R18: BRASCOLA LTDA - | S18: JOINVILLE | T18: SC | U18: 61105060000163 | V18: BRASCOLA LTDA - | W18: RUA DONA FRANCISCA 8300 BLOCO D | X18: ZONA INDUSTRIAL | Y18: JOINVILLE | Z18: SC | AA18: (47 ) 32052727 | AC18: 14011822000182 | AD18: JM DE OLIVEIRA TINTAS ME | AE18: 360 | AF18: TAMP | AG18: JUIZ DE FORA | AH18: MG | AI18: 14011822000182 | AJ18: JM DE OLIVEIRA TINTAS ME | AK18: JUIZ DE FORA | AL18: MG | AM18: TAM | AN18: 000330404 | AO18: 73.4 | AP18: 0.0001 | AQ18: 10 | AR18: 0 | AS18: CP | AT18: LIQUIDADO | AU18: 46262 | AV18: 241.66 | AW18: 001-DIVERSOS | AX18: 001-DIVERSOS | AY18: 1520 | AZ18: COMBINADA | BA18: CO3809041 | BB18: 241.66 | BC18: 212.66 | BD18: 241.66 | BE18: 29 | BF18: 0.12 | BG18: 0 | BH18: 73.4 | BI18: 176.36 | BJ18: 0 | BK18: 18 | BL18: 0 | BM18: 0 | BN18: 3.25 | BO18: 5.5 | BP18: 4.23 | BQ18: 0 | BR18: 0 | BS18: 0 | BT18: 0 | BU18: 0 | BV18: 0 | BW18: 0 | BX18: 0 | BY18: 0 | BZ18: 0 | CA18: 5.32 | CB18: RSCP | CC18: TAMI | CD18: 373.22 | CE18: 0 | CF18: 0 | CG18: 0 | CH18: 0 | CI18: 0 | CJ18: 0 | CK18: 0 | CN18: 0 | CO18: 0 | CP18: 0 | CQ18: 0 | CR18: 0 | CS18: 0 | CT18: 0 | CU18: 48.33 | CV18: FATURA: 12310 | CW18: 48.33 | CX18: 012310 | CY18: 30.09 | CZ18: FATURA: 21534 | DA18: 30.09 | DB18: 021534 | DE18: 0 | DF18: A. | DG18: SC | DH18: JOINVILLE | DI18: 252895738 | DJ18: (47 ) 32052727 | DK18: 0 | DL18: JOI | DM18: 29
A19: 2 | B19: JOI025401-1 | C19: NORMAL | D19: JOIR | E19: JOI | F19: 46240 | G19: MMM1H28 | H19: 42260803098929000789570010000252281003675030 | I19: 61105060000163 | J19: BRASCOLA LTDA - | K19: RUA DONA FRANCISCA 8300 BLOCO D | L19: ZONA INDUSTRIAL | M19: 892 | N19: JOINVILLE | O19: SC | P19: 89219-600 | Q19: 61105060000163 | R19: BRASCOLA LTDA - | S19: JOINVILLE | T19: SC | U19: 61105060000163 | V19: BRASCOLA LTDA - | W19: RUA DONA FRANCISCA 8300 BLOCO D | X19: ZONA INDUSTRIAL | Y19: JOINVILLE | Z19: SC | AA19: (47 ) 32052727 | AC19: 13921752000137 | AD19: BOMDIPEL MATERIAIS DE CONSTRUCAO LTDA - ME | AE19: 356 | AF19: STJP | AG19: POMPEU | AH19: MG | AI19: 13921752000137 | AJ19: BOMDIPEL MATERIAIS DE CONSTRUCAO LTDA - ME | AK19: POMPEU | AL19: MG | AM19: STJ | AN19: 000330407 | AO19: 54.66 | AP19: 0.0001 | AQ19: 9 | AR19: 0 | AS19: CP | AT19: LIQUIDADO | AU19: 46262 | AV19: 248.25 | AW19: 001-DIVERSOS | AX19: 001-DIVERSOS | AY19: 1680.29 | AZ19: COMBINADA | BA19: CO3809055 | BB19: 248.25 | BC19: 218.46 | BD19: 248.25 | BE19: 29.79 | BF19: 0.12 | BG19: 0 | BH19: 54.66 | BI19: 181.6 | BJ19: 0 | BK19: 18 | BL19: 0 | BM19: 0 | BN19: 3.25 | BO19: 5.5 | BP19: 4.23 | BQ19: 0 | BR19: 0 | BS19: 0 | BT19: 0 | BU19: 0 | BV19: 0 | BW19: 0 | BX19: 0 | BY19: 0 | BZ19: 0 | CA19: 5.88 | CB19: RSCP | CC19: RWNI | CD19: 374.77 | CE19: 0 | CF19: 0 | CG19: 0 | CH19: 0 | CI19: 0 | CJ19: 0 | CK19: 0 | CN19: 0 | CO19: 0 | CP19: 0 | CQ19: 0 | CR19: 0 | CS19: 0 | CT19: 0 | CU19: 49.65 | CV19: FATURA: 12310 | CW19: 49.65 | CX19: 012310 | CY19: 51 | CZ19: FATURA: 64592 | DA19: 51 | DB19: 064592 | DE19: 0 | DF19: A. | DG19: SC | DH19: JOINVILLE | DI19: 252895738 | DJ19: (47 ) 32052727 | DK19: 0 | DL19: JOI | DM19: 29.79
A20: 2 | B20: JOI025402-9 | C20: NORMAL | D20: JOIR | E20: JOI | F20: 46240 | G20: MMM1H28 | H20: 42260803098929000789570010000252321003675075 | I20: 61105060000163 | J20: BRASCOLA LTDA - | K20: RUA DONA FRANCISCA 8300 BLOCO D | L20: ZONA INDUSTRIAL | M20: 892 | N20: JOINVILLE | O20: SC | P20: 89219-600 | Q20: 61105060000163 | R20: BRASCOLA LTDA - | S20: JOINVILLE | T20: SC | U20: 61105060000163 | V20: BRASCOLA LTDA - | W20: RUA DONA FRANCISCA 8300 BLOCO D | X20: ZONA INDUSTRIAL | Y20: JOINVILLE | Z20: SC | AA20: (47 ) 32052727 | AC20: 42858274000166 | AD20: PAIOL AGROGURGEL COMERCIO DE FERRAGENS L | AE20: 10 ROTA CIRCUITO DAS AGUAS | AF20: DCCR | AG20: SAO LOURENCO | AH20: MG | AI20: 42858274000166 | AJ20: PAIOL AGROGURGEL COMERCIO DE FERRAGENS L | AK20: SAO LOURENCO | AL20: MG | AM20: DCC | AN20: 000330443 | AO20: 161.47 | AP20: 0.0001 | AQ20: 52 | AR20: 0 | AS20: CP | AT20: LIQUIDADO | AU20: 46262 | AV20: 357.01 | AW20: 001-DIVERSOS | AX20: 001-DIVERSOS | AY20: 4935.52 | AZ20: COMBINADA | BA20: CO3809036 | BB20: 357.01 | BC20: 314.17 | BD20: 357.01 | BE20: 42.84 | BF20: 0.12 | BG20: 0 | BH20: 161.47 | BI20: 256.27 | BJ20: 0 | BK20: 18 | BL20: 0 | BM20: 0 | BN20: 7.4 | BO20: 11 | BP20: 4.23 | BQ20: 0 | BR20: 0 | BS20: 0 | BT20: 0 | BU20: 0 | BV20: 0 | BW20: 0 | BX20: 0 | BY20: 0 | BZ20: 0 | CA20: 17.27 | CB20: RSCP | CC20: ALTR | CD20: 414.16 | CE20: 0 | CF20: 0 | CG20: 0 | CH20: 0 | CI20: 0 | CJ20: 0 | CK20: 0 | CN20: 0 | CO20: 0 | CP20: 0 | CQ20: 0 | CR20: 0 | CS20: 0 | CT20: 0 | CU20: 71.4 | CV20: FATURA: 12310 | CW20: 71.4 | CX20: 012310 | CY20: 124.95 | CZ20: FATURA: 143 | DA20: 324.95 | DB20: 000143 | DE20: 0 | DF20: A. | DG20: SC | DH20: JOINVILLE | DI20: 252895738 | DJ20: (47 ) 32052727 | DK20: 0 | DL20: JOI | DM20: 42.84
A21: 2 | B21: JOI025454-1 | C21: NORMAL | D21: JOIR | E21: JOI | F21: 46241 | G21: MMM1H28 | H21: 42260803098929000789570010000252841003684062 | I21: 61105060000163 | J21: BRASCOLA LTDA - | K21: RUA DONA FRANCISCA 8300 BLOCO D | L21: ZONA INDUSTRIAL | M21: 892 | N21: JOINVILLE | O21: SC | P21: 89219-600 | Q21: 61105060000163 | R21: BRASCOLA LTDA - | S21: JOINVILLE | T21: SC | U21: 61105060000163 | V21: BRASCOLA LTDA - | W21: RUA DONA FRANCISCA 8300 BLOCO D | X21: ZONA INDUSTRIAL | Y21: JOINVILLE | Z21: SC | AA21: (47 ) 32052727 | AC21: 30373444000133 | AD21: GEANDERSON CESAR CAETANO ME | AE21: 359 | AF21: GVRP | AG21: ITABIRA | AH21: MG | AI21: 30373444000133 | AJ21: GEANDERSON CESAR CAETANO ME | AK21: ITABIRA | AL21: MG | AM21: GVR | AN21: 000330493 | AO21: 40.984 | AP21: 0.0001 | AQ21: 9 | AR21: 0 | AS21: CP | AT21: LIQUIDADO | AU21: 46262 | AV21: 220.82 | AW21: 001-DIVERSOS | AX21: 001-DIVERSOS | AY21: 1631.71 | AZ21: COMBINADA | BA21: CO3809055 | BB21: 220.82 | BC21: 194.32 | BD21: 220.82 | BE21: 26.5 | BF21: 0.12 | BG21: 0 | BH21: 40.984 | BI21: 157.63 | BJ21: 0 | BK21: 18 | BL21: 0 | BM21: 0 | BN21: 3.25 | BO21: 5.5 | BP21: 4.23 | BQ21: 0 | BR21: 0 | BS21: 0 | BT21: 0 | BU21: 0 | BV21: 0 | BW21: 0 | BX21: 0 | BY21: 0 | BZ21: 0 | CA21: 5.71 | CB21: RSCP | CC21: RWNI | CD21: 374.33 | CE21: 0 | CF21: 0 | CG21: 0 | CH21: 0 | CI21: 0 | CJ21: 0 | CK21: 0 | CN21: 0 | CO21: 0 | CP21: 0 | CQ21: 0 | CR21: 0 | CS21: 0 | CT21: 0 | CU21: 44.16 | CV21: FATURA: 12323 | CW21: 44.16 | CX21: 012323 | CY21: 81.79 | CZ21: FATURA: 12223 | DA21: 81.79 | DB21: 012223 | DE21: 0 | DF21: A. | DG21: SC | DH21: JOINVILLE | DI21: 252895738 | DJ21: (47 ) 32052727 | DK21: 0 | DL21: JOI | DM21: 26.5
A22: 2 | B22: JOI025455-0 | C22: NORMAL | D22: JOIR | E22: JOI | F22: 46241 | G22: MMM1H28 | H22: 42260803098929000789570010000252851003684078 | I22: 61105060000163 | J22: BRASCOLA LTDA - | K22: RUA DONA FRANCISCA 8300 BLOCO D | L22: ZONA INDUSTRIAL | M22: 892 | N22: JOINVILLE | O22: SC | P22: 89219-600 | Q22: 61105060000163 | R22: BRASCOLA LTDA - | S22: JOINVILLE | T22: SC | U22: 61105060000163 | V22: BRASCOLA LTDA - | W22: RUA DONA FRANCISCA 8300 BLOCO D | X22: ZONA INDUSTRIAL | Y22: JOINVILLE | Z22: SC | AA22: (47 ) 32052727 | AC22: 09342854000120 | AD22: CUNHA MATERIAL DE CONSTRUCAO LTDA ME | AE22: 397 | AF22: GRFI | AG22: DIVINOLANDIA DE MINAS | AH22: MG | AI22: 09342854000120 | AJ22: CUNHA MATERIAL DE CONSTRUCAO LTDA ME | AK22: DIVINOLANDIA DE MINAS | AL22: MG | AM22: GRF | AN22: 000330483 | AO22: 74.328 | AP22: 0.0001 | AQ22: 19 | AR22: 0 | AS22: CP | AT22: LIQUIDADO | AU22: 46262 | AV22: 269.3 | AW22: 001-DIVERSOS | AX22: 001-DIVERSOS | AY22: 3051.01 | AZ22: COMBINADA | BA22: CO3809063 | BB22: 269.3 | BC22: 236.98 | BD22: 269.3 | BE22: 32.32 | BF22: 0.12 | BG22: 0 | BH22: 74.328 | BI22: 193.99 | BJ22: 0 | BK22: 18 | BL22: 0 | BM22: 0 | BN22: 4.58 | BO22: 5.5 | BP22: 4.23 | BQ22: 0 | BR22: 0 | BS22: 0 | BT22: 0 | BU22: 0 | BV22: 0 | BW22: 0 | BX22: 0 | BY22: 0 | BZ22: 0 | CA22: 10.68 | CB22: RSCP | CC22: GRFI | CD22: 389.67 | CE22: 0 | CF22: 0 | CG22: 0 | CH22: 0 | CI22: 0 | CJ22: 0 | CK22: 0 | CN22: 0 | CO22: 0 | CP22: 0 | CQ22: 0 | CR22: 0 | CS22: 0 | CT22: 0 | CU22: 53.86 | CV22: FATURA: 12323 | CW22: 53.86 | CX22: 012323 | CY22: 123.78 | CZ22: FATURA: 130688 | DA22: 138.93 | DB22: 130688 | DE22: 0 | DF22: A. | DG22: SC | DH22: JOINVILLE | DI22: 252895738 | DJ22: (47 ) 32052727 | DK22: 0 | DL22: JOI | DM22: 32.32
A23: 2 | B23: JOI025456-8 | C23: NORMAL | D23: JOIR | E23: JOI | F23: 46241 | G23: MMM1H28 | H23: 42260803098929000789570010000252861003684083 | I23: 61105060000163 | J23: BRASCOLA LTDA - | K23: RUA DONA FRANCISCA 8300 BLOCO D | L23: ZONA INDUSTRIAL | M23: 892 | N23: JOINVILLE | O23: SC | P23: 89219-600 | Q23: 61105060000163 | R23: BRASCOLA LTDA - | S23: JOINVILLE | T23: SC | U23: 61105060000163 | V23: BRASCOLA LTDA - | W23: RUA DONA FRANCISCA 8300 BLOCO D | X23: ZONA INDUSTRIAL | Y23: JOINVILLE | Z23: SC | AA23: (47 ) 32052727 | AC23: 03078191000100 | AD23: COMERCIAL IRMAOS CIMINI LTDA | AE23: 350 | AF23: GVRP | AG23: GOVERNADOR VALADARES | AH23: MG | AI23: 03078191000100 | AJ23: COMERCIAL IRMAOS CIMINI LTDA | AK23: GOVERNADOR VALADARES | AL23: MG | AM23: GVR | AN23: 000330524 | AO23: 121.068 | AP23: 0 | AQ23: 25 | AR23: 0 | AS23: CP | AT23: LIQUIDADO | AU23: 46262 | AV23: 312.23 | AW23: 001-DIVERSOS | AX23: 001-DIVERSOS | AY23: 2766.4 | AZ23: COMBINADA | BA23: CO3809055 | BB23: 312.23 | BC23: 274.76 | BD23: 312.23 | BE23: 37.47 | BF23: 0.12 | BG23: 0 | BH23: 121.068 | BI23: 227.7 | BJ23: 0 | BK23: 18 | BL23: 0 | BM23: 0 | BN23: 4.15 | BO23: 11 | BP23: 4.23 | BQ23: 0 | BR23: 0 | BS23: 0 | BT23: 0 | BU23: 0 | BV23: 0 | BW23: 0 | BX23: 0 | BY23: 0 | BZ23: 0 | CA23: 9.68 | CB23: RSCP | CC23: RWNI | CD23: 385.95 | CE23: 0 | CF23: 0 | CG23: 0 | CH23: 0 | CI23: 0 | CJ23: 0 | CK23: 0 | CN23: 0 | CO23: 0 | CP23: 0 | CQ23: 0 | CR23: 0 | CS23: 0 | CT23: 0 | CU23: 62.45 | CV23: FATURA: 12323 | CW23: 62.45 | CX23: 012323 | CY23: 118.28 | CZ23: FATURA: 12223 | DA23: 118.28 | DB23: 012223 | DE23: 0 | DF23: A. | DG23: SC | DH23: JOINVILLE | DI23: 252895738 | DJ23: (47 ) 32052727 | DK23: 0 | DL23: JOI | DM23: 37.47
A24: 2 | B24: JOI025497-5 | C24: NORMAL | D24: JOIR | E24: JOI | F24: 46244 | G24: MMM1H28 | H24: 42260803098929000789570010000253231003692480 | I24: 61105060000163 | J24: BRASCOLA LTDA - | K24: RUA DONA FRANCISCA 8300 BLOCO D | L24: ZONA INDUSTRIAL | M24: 892 | N24: JOINVILLE | O24: SC | P24: 89219-600 | Q24: 61105060000163 | R24: BRASCOLA LTDA - | S24: JOINVILLE | T24: SC | U24: 61105060000163 | V24: BRASCOLA LTDA - | W24: RUA DONA FRANCISCA 8300 BLOCO D | X24: ZONA INDUSTRIAL | Y24: JOINVILLE | Z24: SC | AA24: (47 ) 32052727 | AC24: 02275530000178 | AD24: MINAS CHAPAS LTDA | AE24: 002 BELO HORIZONTE | AF24: BHZP | AG24: BELO HORIZONTE | AH24: MG | AI24: 02275530000178 | AJ24: MINAS CHAPAS LTDA | AK24: BELO HORIZONTE | AL24: MG | AM24: BHZ | AN24: 000330610 | AO24: 286 | AP24: 0.0001 | AQ24: 1 | AR24: 0 | AS24: CP | AT24: LIQUIDADO | AU24: 46269 | AV24: 506.6 | AW24: 001-DIVERSOS | AX24: 001-DIVERSOS | AY24: 5078.78 | AZ24: COMBINADA | BA24: CO3809017 | BB24: 506.6 | BC24: 445.81 | BD24: 506.6 | BE24: 60.79 | BF24: 0.12 | BG24: 0 | BH24: 286 | BI24: 381.68 | BJ24: 0 | BK24: 18 | BL24: 0 | BM24: 0 | BN24: 7.62 | BO24: 16.5 | BP24: 4.23 | BQ24: 0 | BR24: 0 | BS24: 0 | BT24: 0 | BU24: 0 | BV24: 0 | BW24: 0 | BX24: 0 | BY24: 0 | BZ24: 0 | CA24: 17.78 | CB24: RSCP | CC24: BHZP | CD24: 717.06 | CE24: 0 | CF24: 0 | CG24: 0 | CH24: 0 | CI24: 0 | CJ24: 0 | CK24: 0 | CN24: 0 | CO24: 0 | CP24: 0 | CQ24: 0 | CR24: 0 | CS24: 0 | CT24: 0 | CU24: 101.32 | CV24: FATURA: 12323 | CW24: 101.32 | CX24: 012323 | CY24: 40.04 | CZ24: MAPA: 161 | DA24: 0 | DE24: 0 | DF24: A. | DG24: SC | DH24: JOINVILLE | DI24: 252895738 | DJ24: (47 ) 32052727 | DK24: 0 | DL24: JOI | DM24: 60.79
A25: 2 | B25: JOI025498-3 | C25: NORMAL | D25: JOIR | E25: JOI | F25: 46244 | G25: MMM1H28 | H25: 42260803098929000789570010000253241003692496 | I25: 61105060000163 | J25: BRASCOLA LTDA - | K25: RUA DONA FRANCISCA 8300 BLOCO D | L25: ZONA INDUSTRIAL | M25: 892 | N25: JOINVILLE | O25: SC | P25: 89219-600 | Q25: 61105060000163 | R25: BRASCOLA LTDA - | S25: JOINVILLE | T25: SC | U25: 61105060000163 | V25: BRASCOLA LTDA - | W25: RUA DONA FRANCISCA 8300 BLOCO D | X25: ZONA INDUSTRIAL | Y25: JOINVILLE | Z25: SC | AA25: (47 ) 32052727 | AC25: 21765695000172 | AD25: CHAPADACO FERRAGENS LTDA EPP | AE25: 393 | AF25: STJI | AG25: CHAPADA GAUCHA | AH25: MG | AI25: 21765695000172 | AJ25: CHAPADACO FERRAGENS LTDA EPP | AK25: SAO FRANCISCO | AL25: MG | AM25: STJ | AN25: 000330540 | AO25: 39.12 | AP25: 0.0001 | AQ25: 10 | AR25: 0 | AS25: CP | AT25: LIQUIDADO | AU25: 46269 | AV25: 221.23 | AW25: 001-DIVERSOS | AX25: 001-DIVERSOS | AY25: 1734.34 | AZ25: COMBINADA | BA25: CO3809052 | BB25: 221.23 | BC25: 194.68 | BD25: 221.23 | BE25: 26.55 | BF25: 0.12 | BG25: 0 | BH25: 39.12 | BI25: 157.63 | BJ25: 0 | BK25: 18 | BL25: 0 | BM25: 0 | BN25: 3.25 | BO25: 5.5 | BP25: 4.23 | BQ25: 0 | BR25: 0 | BS25: 0 | BT25: 0 | BU25: 0 | BV25: 0 | BW25: 0 | BX25: 0 | BY25: 0 | BZ25: 0 | CA25: 6.07 | CB25: RSCP | CC25: RMCP | CD25: 375.35 | CE25: 0 | CF25: 0 | CG25: 0 | CH25: 0 | CI25: 0 | CJ25: 0 | CK25: 0 | CN25: 0 | CO25: 0 | CP25: 0 | CQ25: 0 | CR25: 0 | CS25: 0 | CT25: 0 | CU25: 44.25 | CV25: FATURA: 12323 | CW25: 44.25 | CX25: 012323 | CY25: 51 | CZ25: FATURA: 65166 | DA25: 51 | DB25: 065166 | DE25: 0 | DF25: A. | DG25: SC | DH25: JOINVILLE | DI25: 252895738 | DJ25: (47 ) 32052727 | DK25: 0 | DL25: JOI | DM25: 26.55
A26: 2 | B26: JOI025499-1 | C26: NORMAL | D26: JOIR | E26: JOI | F26: 46244 | G26: MMM1H28 | H26: 42260803098929000789570010000253251003692507 | I26: 61105060000163 | J26: BRASCOLA LTDA - | K26: RUA DONA FRANCISCA 8300 BLOCO D | L26: ZONA INDUSTRIAL | M26: 892 | N26: JOINVILLE | O26: SC | P26: 89219-600 | Q26: 61105060000163 | R26: BRASCOLA LTDA - | S26: JOINVILLE | T26: SC | U26: 61105060000163 | V26: BRASCOLA LTDA - | W26: RUA DONA FRANCISCA 8300 BLOCO D | X26: ZONA INDUSTRIAL | Y26: JOINVILLE | Z26: SC | AA26: (47 ) 32052727 | AC26: 04505326000121 | AD26: COMERCIAL FERRONORTE COMERCIO INDUSTRIA E SERVICOS LTDA | AE26: 394 | AF26: VEAI | AG26: MONTES CLAROS | AH26: MG | AI26: 04505326000121 | AJ26: COMERCIAL FERRONORTE COMERCIO INDUSTRIA E SERVICOS LTDA | AK26: MONTES CLAROS | AL26: MG | AM26: VEA | AN26: 000330541 | AO26: 90.212 | AP26: 0.0001 | AQ26: 19 | AR26: 0 | AS26: CP | AT26: LIQUIDADO | AU26: 46269 | AV26: 270.92 | AW26: 001-DIVERSOS | AX26: 001-DIVERSOS | AY26: 3337.82 | AZ26: COMBINADA | BA26: CO3809060 | BB26: 270.92 | BC26: 238.41 | BD26: 270.92 | BE26: 32.51 | BF26: 0.12 | BG26: 0 | BH26: 90.212 | BI26: 193.99 | BJ26: 0 | BK26: 18 | BL26: 0 | BM26: 0 | BN26: 5.01 | BO26: 5.5 | BP26: 4.23 | BQ26: 0 | BR26: 0 | BS26: 0 | BT26: 0 | BU26: 0 | BV26: 0 | BW26: 0 | BX26: 0 | BY26: 0 | BZ26: 0 | CA26: 11.68 | CB26: RSCP | CC26: VEAI | CD26: 393.38 | CE26: 0 | CF26: 0 | CG26: 0 | CH26: 0 | CI26: 0 | CJ26: 0 | CK26: 0 | CN26: 0 | CO26: 0 | CP26: 0 | CQ26: 0 | CR26: 0 | CS26: 0 | CT26: 0 | CU26: 54.18 | CV26: FATURA: 12323 | CW26: 54.18 | CX26: 012323 | CY26: 81.28 | CZ26: MAPA: 0 | DA26: =CY26 -> 81.28 | DE26: 0 | DF26: A. | DG26: SC | DH26: JOINVILLE | DI26: 252895738 | DJ26: (47 ) 32052727 | DK26: 0 | DL26: JOI | DM26: 32.51
A27: 2 | B27: JOI025500-9 | C27: NORMAL | D27: JOIR | E27: JOI | F27: 46244 | G27: MMM1H28 | H27: 42260803098929000789570010000253261003692512 | I27: 61105060000163 | J27: BRASCOLA LTDA - | K27: RUA DONA FRANCISCA 8300 BLOCO D | L27: ZONA INDUSTRIAL | M27: 892 | N27: JOINVILLE | O27: SC | P27: 89219-600 | Q27: 61105060000163 | R27: BRASCOLA LTDA - | S27: JOINVILLE | T27: SC | U27: 61105060000163 | V27: BRASCOLA LTDA - | W27: RUA DONA FRANCISCA 8300 BLOCO D | X27: ZONA INDUSTRIAL | Y27: JOINVILLE | Z27: SC | AA27: (47 ) 32052727 | AC27: 01177077000102 | AD27: LOJA PINHEIRO CONFECCOES E ARMARINHO LTDA | AE27: 398 | AF27: GRFP | AG27: TEOFILO OTONI | AH27: MG | AI27: 01177077000102 | AJ27: LOJA PINHEIRO CONFECCOES E ARMARINHO LTDA | AK27: TEOFILO OTONI | AL27: MG | AM27: GRF | AN27: 000330547 | AO27: 45 | AP27: 0.0001 | AQ27: 25 | AR27: 0 | AS27: CP | AT27: LIQUIDADO | AU27: 46269 | AV27: 221.92 | AW27: 001-DIVERSOS | AX27: 001-DIVERSOS | AY27: 1907.49 | AZ27: COMBINADA | BA27: CO3809065 | BB27: 221.92 | BC27: 195.29 | BD27: 221.92 | BE27: 26.63 | BF27: 0.12 | BG27: 0 | BH27: 45 | BI27: 157.63 | BJ27: 0 | BK27: 18 | BL27: 0 | BM27: 0 | BN27: 3.25 | BO27: 5.5 | BP27: 4.23 | BQ27: 0 | BR27: 0 | BS27: 0 | BT27: 0 | BU27: 0 | BV27: 0 | BW27: 0 | BX27: 0 | BY27: 0 | BZ27: 0 | CA27: 6.68 | CB27: RSCP | CC27: LTOI | CD27: 377.09 | CE27: 0 | CF27: 0 | CG27: 0 | CH27: 0 | CI27: 0 | CJ27: 0 | CK27: 0 | CN27: 0 | CO27: 0 | CP27: 0 | CQ27: 0 | CR27: 0 | CS27: 0 | CT27: 0 | CU27: 44.38 | CV27: FATURA: 12323 | CW27: 44.38 | CX27: 012323 | CY27: 103.05 | CZ27: FATURA: 130688 | DA27: 115.34 | DB27: 130688 | DE27: 0 | DF27: A. | DG27: SC | DH27: JOINVILLE | DI27: 252895738 | DJ27: (47 ) 32052727 | DK27: 0 | DL27: JOI | DM27: 26.63
A28: 2 | B28: JOI025501-7 | C28: NORMAL | D28: JOIR | E28: JOI | F28: 46244 | G28: MMM1H28 | H28: 42260803098929000789570010000253271003692528 | I28: 61105060000163 | J28: BRASCOLA LTDA - | K28: RUA DONA FRANCISCA 8300 BLOCO D | L28: ZONA INDUSTRIAL | M28: 892 | N28: JOINVILLE | O28: SC | P28: 89219-600 | Q28: 61105060000163 | R28: BRASCOLA LTDA - | S28: JOINVILLE | T28: SC | U28: 61105060000163 | V28: BRASCOLA LTDA - | W28: RUA DONA FRANCISCA 8300 BLOCO D | X28: ZONA INDUSTRIAL | Y28: JOINVILLE | Z28: SC | AA28: (47 ) 32052727 | AC28: 63792748000194 | AD28: 63.792.748 GABRIEL GUIMARAES DE MATOS | AE28: 332 | AF28: BHZP | AG28: LAGOA SANTA | AH28: MG | AI28: 63792748000194 | AJ28: 63.792.748 GABRIEL GUIMARAES DE MATOS | AK28: LAGOA SANTA | AL28: MG | AM28: BHZ | AN28: 000330550 | AO28: 69.12 | AP28: 0.0001 | AQ28: 39 | AR28: 0 | AS28: CP | AT28: LIQUIDADO | AU28: 46269 | AV28: 198.91 | AW28: 001-DIVERSOS | AX28: 001-DIVERSOS | AY28: 3046.21 | AZ28: COMBINADA | BA28: CO3809017 | BB28: 198.91 | BC28: 175.04 | BD28: 198.91 | BE28: 23.87 | BF28: 0.12 | BG28: 0 | BH28: 69.12 | BI28: 132.08 | BJ28: 0 | BK28: 18 | BL28: 0 | BM28: 0 | BN28: 4.57 | BO28: 5.5 | BP28: 4.23 | BQ28: 0 | BR28: 0 | BS28: 0 | BT28: 0 | BU28: 0 | BV28: 0 | BW28: 0 | BX28: 0 | BY28: 0 | BZ28: 0 | CA28: 10.66 | CB28: RSCP | CC28: BHZP | CD28: 389.56 | CE28: 0 | CF28: 0 | CG28: 0 | CH28: 0 | CI28: 0 | CJ28: 0 | CK28: 0 | CN28: 0 | CO28: 0 | CP28: 0 | CQ28: 0 | CR28: 0 | CS28: 0 | CT28: 0 | CU28: 39.78 | CV28: FATURA: 12323 | CW28: 39.78 | CX28: 012323 | CY28: 15 | CZ28: MAPA: 161 | DA28: 0 | DE28: 0 | DF28: A. | DG28: SC | DH28: JOINVILLE | DI28: 252895738 | DJ28: (47 ) 32052727 | DK28: 0 | DL28: JOI | DM28: 23.87
A29: 2 | B29: JOI025502-5 | C29: NORMAL | D29: JOIR | E29: JOI | F29: 46244 | G29: MMM1H28 | H29: 42260803098929000789570010000253281003692533 | I29: 61105060000163 | J29: BRASCOLA LTDA - | K29: RUA DONA FRANCISCA 8300 BLOCO D | L29: ZONA INDUSTRIAL | M29: 892 | N29: JOINVILLE | O29: SC | P29: 89219-600 | Q29: 61105060000163 | R29: BRASCOLA LTDA - | S29: JOINVILLE | T29: SC | U29: 61105060000163 | V29: BRASCOLA LTDA - | W29: RUA DONA FRANCISCA 8300 BLOCO D | X29: ZONA INDUSTRIAL | Y29: JOINVILLE | Z29: SC | AA29: (47 ) 32052727 | AC29: 21513577000177 | AD29: ELETRO BRAGA LTDA | AE29: 363 | AF29: TAMR | AG29: SAO JOAO DEL REI | AH29: MG | AI29: 21513577000177 | AJ29: ELETRO BRAGA LTDA | AK29: SAO JOAO DEL REI | AL29: MG | AM29: TAM | AN29: 000330554 | AO29: 103.632 | AP29: 0.0001 | AQ29: 23 | AR29: 0 | AS29: CP | AT29: LIQUIDADO | AU29: 46269 | AV29: 261.52 | AW29: 001-DIVERSOS | AX29: 001-DIVERSOS | AY29: 3165.42 | AZ29: COMBINADA | BA29: CO3809042 | BB29: 261.52 | BC29: 230.14 | BD29: 261.52 | BE29: 31.38 | BF29: 0.12 | BG29: 0 | BH29: 103.632 | BI29: 181.08 | BJ29: 0 | BK29: 18 | BL29: 0 | BM29: 0 | BN29: 4.75 | BO29: 11 | BP29: 4.23 | BQ29: 0 | BR29: 0 | BS29: 0 | BT29: 0 | BU29: 0 | BV29: 0 | BW29: 0 | BX29: 0 | BY29: 0 | BZ29: 0 | CA29: 11.08 | CB29: RSCP | CC29: TAMR | CD29: 391.15 | CE29: 0 | CF29: 0 | CG29: 0 | CH29: 0 | CI29: 0 | CJ29: 0 | CK29: 0 | CN29: 0 | CO29: 0 | CP29: 0 | CQ29: 0 | CR29: 0 | CS29: 0 | CT29: 0 | CU29: 52.3 | CV29: FATURA: 12323 | CW29: 52.3 | CX29: 012323 | CY29: 51.82 | CZ29: FATURA: 21744 | DA29: 51.82 | DB29: 021744 | DE29: 0 | DF29: A. | DG29: SC | DH29: JOINVILLE | DI29: 252895738 | DJ29: (47 ) 32052727 | DK29: 0 | DL29: JOI | DM29: 31.38
A30: 2 | B30: JOI025503-3 | C30: NORMAL | D30: JOIR | E30: JOI | F30: 46244 | G30: MMM1H28 | H30: 42260803098929000789570010000253291003692549 | I30: 61105060000163 | J30: BRASCOLA LTDA - | K30: RUA DONA FRANCISCA 8300 BLOCO D | L30: ZONA INDUSTRIAL | M30: 892 | N30: JOINVILLE | O30: SC | P30: 89219-600 | Q30: 61105060000163 | R30: BRASCOLA LTDA - | S30: JOINVILLE | T30: SC | U30: 61105060000163 | V30: BRASCOLA LTDA - | W30: RUA DONA FRANCISCA 8300 BLOCO D | X30: ZONA INDUSTRIAL | Y30: JOINVILLE | Z30: SC | AA30: (47 ) 32052727 | AC30: 55816370000193 | AD30: NOVA ALVORADA MATERIAIS PARA CONSTRUCAO LTDA | AE30: 6 ROTA POCOS DE CALDAS | AF30: DCCR | AG30: POCOS DE CALDAS | AH30: MG | AI30: 55816370000193 | AJ30: NOVA ALVORADA MATERIAIS PARA CONSTRUCAO LTDA | AK30: POCOS DE CALDAS | AL30: MG | AM30: DCC | AN30: 000330569 | AO30: 361.88 | AP30: 0.0001 | AQ30: 1 | AR30: 0 | AS30: CP | AT30: LIQUIDADO | AU30: 46269 | AV30: 683.1 | AW30: 001-DIVERSOS | AX30: 001-DIVERSOS | AY30: 8021.33 | AZ30: COMBINADA | BA30: CO3809036 | BB30: 683.1 | BC30: 601.13 | BD30: 683.1 | BE30: 81.97 | BF30: 0.12 | BG30: 0 | BH30: 361.88 | BI30: 516.8 | BJ30: 0 | BK30: 18 | BL30: 0 | BM30: 0 | BN30: 12.03 | BO30: 22 | BP30: 4.23 | BQ30: 0 | BR30: 0 | BS30: 0 | BT30: 0 | BU30: 0 | BV30: 0 | BW30: 0 | BX30: 0 | BY30: 0 | BZ30: 0 | CA30: 28.07 | CB30: RSCP | CC30: ALTR | CD30: 1020.92 | CE30: 0 | CF30: 0 | CG30: 0 | CH30: 0 | CI30: 0 | CJ30: 0 | CK30: 0 | CN30: 0 | CO30: 0 | CP30: 0 | CQ30: 0 | CR30: 0 | CS30: 0 | CT30: 0 | CU30: 136.62 | CV30: FATURA: 12323 | CW30: 136.62 | CX30: 012323 | CY30: 239.09 | CZ30: FATURA: 143 | DA30: 239.09 | DB30: 000143 | DE30: 0 | DF30: A. | DG30: SC | DH30: JOINVILLE | DI30: 252895738 | DJ30: (47 ) 32052727 | DK30: 0 | DL30: JOI | DM30: 81.97
A31: 2 | B31: JOI025504-1 | C31: NORMAL | D31: JOIR | E31: JOI | F31: 46244 | G31: MMM1H28 | H31: 42260803098929000789570010000253301003692558 | I31: 61105060000163 | J31: BRASCOLA LTDA - | K31: RUA DONA FRANCISCA 8300 BLOCO D | L31: ZONA INDUSTRIAL | M31: 892 | N31: JOINVILLE | O31: SC | P31: 89219-600 | Q31: 61105060000163 | R31: BRASCOLA LTDA - | S31: JOINVILLE | T31: SC | U31: 61105060000163 | V31: BRASCOLA LTDA - | W31: RUA DONA FRANCISCA 8300 BLOCO D | X31: ZONA INDUSTRIAL | Y31: JOINVILLE | Z31: SC | AA31: (47 ) 32052727 | AC31: 24178418000151 | AD31: EZEQUIAS SELMIEL DE CARVALHO | AE31: 3 ROTA ITAJUBA | AF31: DCCR | AG31: ITAJUBA | AH31: MG | AI31: 24178418000151 | AJ31: EZEQUIAS SELMIEL DE CARVALHO | AK31: ITAJUBA | AL31: MG | AM31: DCC | AN31: 000330578 | AO31: 55.376 | AP31: 0.0001 | AQ31: 8 | AR31: 0 | AS31: CP | AT31: LIQUIDADO | AU31: 46269 | AV31: 228.9 | AW31: 001-DIVERSOS | AX31: 001-DIVERSOS | AY31: 1534.86 | AZ31: COMBINADA | BA31: CO3809036 | BB31: 228.9 | BC31: 201.43 | BD31: 228.9 | BE31: 27.47 | BF31: 0.12 | BG31: 0 | BH31: 55.376 | BI31: 165.08 | BJ31: 0 | BK31: 18 | BL31: 0 | BM31: 0 | BN31: 3.25 | BO31: 5.5 | BP31: 4.23 | BQ31: 0 | BR31: 0 | BS31: 0 | BT31: 0 | BU31: 0 | BV31: 0 | BW31: 0 | BX31: 0 | BY31: 0 | BZ31: 0 | CA31: 5.37 | CB31: RSCP | CC31: ALTR | CD31: 373.35 | CE31: 0 | CF31: 0 | CG31: 0 | CH31: 0 | CI31: 0 | CJ31: 0 | CK31: 0 | CN31: 0 | CO31: 0 | CP31: 0 | CQ31: 0 | CR31: 0 | CS31: 0 | CT31: 0 | CU31: 45.78 | CV31: FATURA: 12323 | CW31: 45.78 | CX31: 012323 | CY31: 80.12 | CZ31: FATURA: 143 | DA31: 80.12 | DB31: 000143 | DE31: 0 | DF31: A. | DG31: SC | DH31: JOINVILLE | DI31: 252895738 | DJ31: (47 ) 32052727 | DK31: 0 | DL31: JOI | DM31: 27.47
A32: 2 | B32: JOI025505-0 | C32: NORMAL | D32: JOIR | E32: JOI | F32: 46244 | G32: MMM1H28 | H32: 42260803098929000789570010000253311003692563 | I32: 61105060000163 | J32: BRASCOLA LTDA - | K32: RUA DONA FRANCISCA 8300 BLOCO D | L32: ZONA INDUSTRIAL | M32: 892 | N32: JOINVILLE | O32: SC | P32: 89219-600 | Q32: 61105060000163 | R32: BRASCOLA LTDA - | S32: JOINVILLE | T32: SC | U32: 61105060000163 | V32: BRASCOLA LTDA - | W32: RUA DONA FRANCISCA 8300 BLOCO D | X32: ZONA INDUSTRIAL | Y32: JOINVILLE | Z32: SC | AA32: (47 ) 32052727 | AC32: 76639285004245 | AD32: FERRAGENS NEGRAO COMERCIAL LTDA | AE32: 010 RIBEIRAO DAS NEVES | AF32: BHZP | AG32: RIBEIRAO DAS NEVES | AH32: MG | AI32: 76639285004245 | AJ32: FERRAGENS NEGRAO COMERCIAL LTDA | AK32: RIBEIRAO DAS NEVES | AL32: MG | AM32: BHZ | AN32: 000330638 | AO32: 103.176 | AP32: 0.0001 | AQ32: 18 | AR32: 0 | AS32: CP | AT32: LIQUIDADO | AU32: 46269 | AV32: 234.68 | AW32: 001-DIVERSOS | AX32: 001-DIVERSOS | AY32: 2198.63 | AZ32: COMBINADA | BA32: CO3809017 | BB32: 234.68 | BC32: 206.52 | BD32: 234.68 | BE32: 28.16 | BF32: 0.12 | BG32: 0 | BH32: 103.176 | BI32: 162.29 | BJ32: 0 | BK32: 18 | BL32: 0 | BM32: 0 | BN32: 3.3 | BO32: 11 | BP32: 4.23 | BQ32: 0 | BR32: 0 | BS32: 0 | BT32: 0 | BU32: 0 | BV32: 0 | BW32: 0 | BX32: 0 | BY32: 0 | BZ32: 0 | CA32: 7.7 | CB32: RSCP | CC32: BHZP | CD32: 379.99 | CE32: 0 | CF32: 0 | CG32: 0 | CH32: 0 | CI32: 0 | CJ32: 0 | CK32: 0 | CN32: 0 | CO32: 0 | CP32: 0 | CQ32: 0 | CR32: 0 | CS32: 0 | CT32: 0 | CU32: 46.94 | CV32: FATURA: 12323 | CW32: 46.94 | CX32: 012323 | CY32: 15 | CZ32: MAPA: 161 | DA32: 0 | DE32: 0 | DF32: A. | DG32: SC | DH32: JOINVILLE | DI32: 252895738 | DJ32: (47 ) 32052727 | DK32: 0 | DL32: JOI | DM32: 28.16
