Workbook

Sheet BASE
B19: CLIENTE: | C19: Central do Frete
B20: CNPJ: | C20: 05855974000170
B21: LOCAL REMETENTE: | C21: São Paulo
B22: TIPO DE FRETE: | C22: CIF

Sheet RESULTADO DIRETO
B3: COMPETENCIA | D3: TOTAL GERAL | L3: CUSTOS | P3: PESO 2024 | S3: 70449976
B4: FRETE | G4: CUSTOS | L4: Desp. Operacional | N4: 10313790 | P4: DESPESA ADMINISTRATIVA 2024 | S4: 15734290
B5: VALOR | D5: =VLOOKUP('RESULTADO DIRETO'!D3,FONTES!B5:I15,5,) -> 77673.43 | G5: Custo Operacional | I5: =VLOOKUP(D3,FONTES!B5:I15,8,) -> 37010.735 | L5: Carga e Descarga | N5: 4671731 | P5: RATEIO | S5: =S4/S3 -> 0.22333989
B6: Receita por kg | D6: =D5/D24 -> 2.3926233 | G6: Focal (agendamento) | L6: Motorista | N6: -2454302.6
B7: Tem Subst.Trib.? | G7: Seguro Acidente (0,014%) com iof | I7: =($D$25*0.01%)*7.38%+($D$25*0.01%) -> 122.27045 | L7: TOTAL | N7: =SUM(N4:N6) -> 12531218 | P7: FATURAMENTO | S7: 85634757
B8: Aliq. | C8: 0.12 | D8: =VLOOKUP('RESULTADO DIRETO'!D3,FONTES!B5:I15,3,) -> 9075.3001 | E8: =IF(D7=$A$2,D5*C8,$A$11) -> 9320.8116 | G8: Seguro Roubo (0,014%) com iof | I8: =($D$25*0.01%)*7.38%+($D$25*0.01%) -> 122.27045 | L8: Desp. Frota | N8: 1301293 | P8: Avarias S/ | S8: 600078
G9: Custo Indenizações | L9: Diárias | N9: -306752 | P9: FATURAMENTO | S9: =S8/S7 -> 0.0070074117
B10: IMPOSTOS | G10: Custo Ajudantes extras/entregas | L10: Lavação | N10: -54194
B11: TRIBUTO | C11: ALÍQUOTA | D11: VALOR | G11: Comissão Comercial/Freelancer | L11: Sinistro | N11: -37032
B12: ICMS | D12: =VLOOKUP(D3,FONTES!B5:I15,3,) -> 9075.3001 | F12: =N27 -> 0.20906161 | G12: RATEIO DESP. ADMINIST./apoio op | I12: ='CUSTO NOVA'!X214 -> 4052.9692 | J12: =I12/D5 -> 0.052179609 | L12: Reboque | N12: -16900
B13: INSS DESON. 1,2 | F13: =N15 -> 0.19042701 | G13: RATEIO DESP. CLT operacional | I13: ='CUSTO NOVA'!Z214 -> 2820.1539 | J13: =I13/D5 -> 0.036307833 | L13: Gerenciamento de Risco | N13: -2055
B14: ISS | C14: 0 | D14: =IF(D5="","",(D5*C14)) -> 0 | G14: TOTAL CUSTOS | I14: =SUM(I5:I13) -> 44128.399 | J14: =SUM(J12:J13) -> 0.088487442 | L14: TOTAL | N14: =SUM(N8:N13) -> 884360
B15: PIS | C15: 0.052 | D15: =D5*C15 -> 4039.0184 | L15: RATEIO | N15: =(N7+N14)/S3 -> 0.19042701
B16: COFINS | G16: APURAÇÃO DO RESULTADO
B17: IRPJ | G17: VALOR BRUTO | I17: =D5 -> 77673.43
B18: CSLL | G18: ( - ) IMPOSTOS | I18: =D19*-1 -> -13114.318
B19: TOTAL TRIBITOS | D19: =SUM(D12:D18) -> 13114.318 | G19: ( - ) CUSTOS | I19: =I14*-1 -> -44128.399
L20: CUSTOS
B21: VALOR RECEITA LIQUIDA: | D21: =D5-D19 -> 64559.112 | L21: Despesa Adminstrativa | N21: 15734290
G22: VALOR LIQUIDO | I22: =SUM(I17:I21) -> 20430.712 | L22: Boletos | N22: 76586
B23: INFORMAÇÕES EXTRAS | G23: % | I23: =I22*100%/I17 -> 0.26303348 | L23: Target | N23: 12917
B24: Tonelada | D24: =VLOOKUP(D3,FONTES!B5:I15,4,) -> 32463.71 | L24: Multa Processo RJ | N24: -306546.52
B25: Valor de NF | D25: =VLOOKUP(D3,FONTES!B5:I15,7,) -> 1138670.6 | G25: QTD CTRC | H25: 82 | I25: =SUM(I26:I27) -> 1 | L25: Manutenções/Instalações Predial/Balanço Patrimonial | N25: -788861
B26: Redespacho | D26: =VLOOKUP(D3,FONTES!B5:I15,6,) -> 16765.91 | E26: =D26/D5 -> 0.21585128 | G26: Bases | H26: 16 | I26: =H26/H25 -> 0.19512195 | L26: TOTAL | N26: =SUM(N21:N25) -> 14728385
G27: Redespachos | H27: 66 | I27: =H27/H25 -> 0.80487805 | L27: RATEIO | N27: =N26/S3 -> 0.20906161
B28: Fat. cte Redespacho | D28: 21962.954 | E28: =D26/D28 -> 0.76337225
B29: Excluído por estar inclusa no Rateio Desp. ADM/OP
B30: Tonelada

Sheet FONTES
B5: COMPETENCIA | C5: TOTAL CTRC | D5: IMPOSTOS | E5: TONELADA | F5: FRETE | G5: REDESPACHO | H5: VALOR MERCADORIA | I5: TOTAL
B6: jan | C6: ='CUSTO NOVA'!I214 -> 82 | D6: ='CUSTO NOVA'!AF214 -> 9075.3001 | E6: ='CUSTO NOVA'!L214 -> 32463.71 | F6: ='CUSTO NOVA'!M214 -> 77673.43 | G6: ='CUSTO NOVA'!T214 -> 16765.91 | H6: ='CUSTO NOVA'!J214 -> 1138670.6 | I6: ='CUSTO NOVA'!V214 -> 37010.735
B7: feb
B8: mar
B9: apr
B10: may
B11: jun
B12: jul
B13: aug
B14: sep
B15: Total Geral | C15: =SUM(C6:C14) -> 82 | D15: =SUM(D6:D14) -> 9075.3001 | E15: =SUM(E6:E14) -> 32463.71 | F15: =SUM(F6:F14) -> 77673.43 | G15: =SUM(G6:G14) -> 16765.91 | H15: =SUM(H6:H14) -> 1138670.6 | I15: =SUM(I6:I14) -> 37010.735

Sheet RESULTADO REDESPACHO

Sheet BASE DADOS
A1: 1 | B1: Serie/Numero CTRC | C1: Tipo do Documento | D1: Praca Expedidora | E1: Unidade Emissora | F1: Data de Emissao | G1: Placa de Coleta | H1: Chave CT-e | I1: CNPJ Remetente | J1: Cliente Remetente | K1: Endereco do Remetente | L1: Bairro do Remetente | M1: Setor de Coleta | N1: Cidade do Remetente | O1: UF do Remetente | P1: CEP do Remetente | Q1: CNPJ Expedidor | R1: Cliente Expedidor | S1: Cidade do Expedidor | T1: UF do Expedidor | U1: CNPJ Pagador | V1: Cliente Pagador | W1: Endereco do Pagador | X1: Bairro do Pagador | Y1: Cidade do Pagador | Z1: UF do Pagador | AA1: Fone do Pagador | AB1: Segmento do Pagador | AC1: CNPJ Destinatario | AD1: Cliente Destinatario | AE1: Setor de Destino | AF1: Praca de Destino | AG1: Cidade do Destinatario | AH1: UF do Destinatario | AI1: CNPJ Recebedor | AJ1: Cliente Recebedor | AK1: Cidade de Entrega | AL1: UF de Entrega | AM1: Unidade Receptora | AN1: Numero da Nota Fiscal | AO1: Peso Real em Kg | AP1: Cubagem em m3 | AQ1: Quantidade de Volumes | AR1: Quantidade de Pares | AS1: Tipo do Frete | AT1: Tipo de Baixa | AU1: Data da Liquidacao | AV1: Valor Liquidado | AW1: Mercadoria | AX1: Especie | AY1: Valor da Mercadoria | AZ1: Tipo de Calculo | BA1: Tabela de Calculo | BB1: Valor do Frete | BC1: Valor do Frete sem ICMS | BD1: Base Calculo ICMS/ISS | BE1: Valor do ICMS | BF1: Aliquota | BG1: Valor do ISS | BH1: Peso Calculado em Kg | BI1: Frete Peso | BJ1: Frete Valor | BK1: Despacho | BL1: CAT | BM1: ITR | BN1: GRIS | BO1: Pedagio | BP1: TAS | BQ1: TDA | BR1: Suframa | BS1: Dev Canhoto NF | BT1: Reembolso | BU1: Outros | BV1: Coleta | BW1: TDC | BX1: TDE | BY1: TAR | BZ1: TRT | CA1: POS | CB1: Praca Comercial Origem | CC1: Praca Comercial Destino | CD1: Frete NTC | CE1: Frete Entrega | CF1: Separacao | CG1: Capatazia | CH1: Veiculo Dedicado | CI1: Paletizacao | CJ1: CO2 | CK1: RDC | CL1: CTRC Origem | CM1: CTe Origem | CN1: Valor do Frete do CTRC Origem | CO1: TDC CTRC Origem | CP1: TDE CTRC Origem | CQ1: TAR CTRC Origem | CR1: TRT CTRC Origem | CS1: TDA CTRC Origem | CT1: Valor do ICMS origem | CU1: Valor da Comissao de Expedicao | CV1: Rel de Comissao de Expedicao | CW1: Valor da Comissao Exp Creditada | CX1: Fatura do Subcon Exp Conferida Opcao 607 | CY1: Valor da Comissao de Recepcao | CZ1: Rel de Comissao de Recepcao | DA1: Valor da Comissao Rec Creditada | DB1: Fatura do Subcon Rec Conferida Opcao 607 | DE1: Adicional de Frete | DF1: ABC Pagador | DG1: UF origem da prestacao | DH1: Cidade origem da prestacao | DI1: IE cliente remetente | DJ1: Fone Remetente | DK1: Agendamento | DL1: Unidade Responsavel Pagador | DM1: Imposto Repassado
A2: 2 | B2: BHZ267694-0 | C2: NORMAL | D2: BHZP | E2: BHZ | F2: 46255 | G2: DJB4058 | H2: 31260803098929000355570010003892621003772782 | I2: 21260419000152 | J2: ESFERA ESTAMPARIA DE FERRO E A | K2: RODOVIA MG 431 S/N KM 45,177 | L2: SANTA MONICA | M2: 001 | N2: ITAUNA | O2: MG | P2: 35681-247 | Q2: 21260419000152 | R2: ESFERA ESTAMPARIA DE FERRO E A | S2: ITAUNA | T2: MG | U2: 05094003000155 | V2: COLSON DO BRASIL LTDA | W2: RUA DAS PALMEIRAS 350 | X2: CAPELA VELHA | Y2: ARAUCARIA | Z2: PR | AA2: (41 ) 38887555 | AC2: 05094003000155 | AD2: COLSON DO BRASIL LTDA | AE2: 002 SETOR I- FROTA | AF2: CTBP | AG2: ARAUCARIA | AH2: PR | AI2: 05094003000155 | AJ2: COLSON DO BRASIL LTDA | AK2: ARAUCARIA | AL2: PR | AM2: CTB | AN2: 000147931 | AO2: 47 | AP2: 0 | AQ2: 3 | AR2: 0 | AS2: FP | AT2: LIQUIDADO | AU2: 46267 | AV2: 172.2 | AW2: 001-DIVERSOS | AX2: 054-PNEUS E CAMARAS DE AR | AY2: 1057.88 | AZ2: COMBINADA | BA2: CO3365294 | BB2: 172.2 | BC2: 151.54 | BD2: 172.2 | BE2: 20.66 | BF2: 0.12 | BG2: 0 | BH2: 47 | BI2: 110.1 | BJ2: 0 | BK2: 17 | BL2: 0 | BM2: 9.76 | BN2: 2.25 | BO2: 5.5 | BP2: 3.23 | BQ2: 0 | BR2: 0 | BS2: 0 | BT2: 0 | BU2: 0 | BV2: 0 | BW2: 0 | BX2: 0 | BY2: 0 | BZ2: 0 | CA2: 3.7 | CB2: RWNI | CC2: CTBP | CD2: 378.38 | CE2: 0 | CF2: 0 | CG2: 0 | CH2: 0 | CI2: 0 | CJ2: 0 | CK2: 0 | CN2: 0 | CO2: 0 | CP2: 0 | CQ2: 0 | CR2: 0 | CS2: 0 | CT2: 0 | CU2: 15 | CV2: MAPA: 162 | CW2: 0 | CY2: 12 | CZ2: MAPA: 162 | DA2: 0 | DE2: 0 | DF2: A. | DG2: MG | DH2: ITAUNA | DI2: 3380715350028 | DJ2: (37 ) 32494800 | DK2: 0 | DL2: CTB | DM2: 20.66
A3: 2 | B3: CTB070615-9 | C3: NORMAL | D3: CTBP | E3: CTB | F3: 46237 | G3: DQB8989 | H3: 41260803098929000606570010000715071003657121 | I3: 05094003000155 | J3: COLSON DO BRASIL LTDA | K3: RUA DAS PALMEIRAS 350 | L3: CAPELA VELHA | M3: 002 | N3: ARAUCARIA | O3: PR | P3: 83705-500 | Q3: 05094003000155 | R3: COLSON DO BRASIL LTDA | S3: ARAUCARIA | T3: PR | U3: 05094003000155 | V3: COLSON DO BRASIL LTDA | W3: RUA DAS PALMEIRAS 350 | X3: CAPELA VELHA | Y3: ARAUCARIA | Z3: PR | AA3: (41 ) 38887555 | AC3: 23476033000884 | AD3: BMB MATERIAL DE CONSTRUCAO S.A. | AE3: RIO RIO DE JANEIRO | AF3: RJOP | AG3: RIO DE JANEIRO | AH3: RJ | AI3: 23476033000884 | AJ3: BMB MATERIAL DE CONSTRUCAO S.A. | AK3: RIO DE JANEIRO | AL3: RJ | AM3: RJO | AN3: 000188725 | AO3: 93.93 | AP3: 0 | AQ3: 8 | AR3: 0 | AS3: CP | AT3: LIQUIDADO | AU3: 46253 | AV3: 460.4 | AW3: 001-DIVERSOS | AX3: 001-DIVERSOS | AY3: 3892.48 | AZ3: COMBINADA | BA3: CO3365267 | BB3: 460.4 | BC3: 405.15 | BD3: 460.4 | BE3: 55.25 | BF3: 0.12 | BG3: 0 | BH3: 93.93 | BI3: 100.2 | BJ3: 0 | BK3: 17 | BL3: 0 | BM3: 9.76 | BN3: 5.84 | BO3: 5.5 | BP3: 3.23 | BQ3: 0 | BR3: 0 | BS3: 0 | BT3: 0 | BU3: 0 | BV3: 0 | BW3: 0 | BX3: 250 | BY3: 0 | BZ3: 0 | CA3: 13.62 | CB3: CTBP | CC3: RJOP | CD3: 400.59 | CE3: 0 | CF3: 0 | CG3: 0 | CH3: 0 | CI3: 0 | CJ3: 0 | CK3: 0 | CN3: 0 | CO3: 0 | CP3: 0 | CQ3: 0 | CR3: 0 | CS3: 0 | CT3: 0 | CU3: 14.09 | CV3: MAPA: 161 | CW3: 0 | CY3: 18 | CZ3: MAPA: 161 | DA3: 0 | DE3: 0 | DF3: A. | DG3: PR | DH3: ARAUCARIA | DI3: 9026067267 | DJ3: (41 ) 38887555 | DK3: 0 | DL3: CTB | DM3: 55.25
A4: 2 | B4: CTB070616-7 | C4: NORMAL | D4: CTBP | E4: CTB | F4: 46237 | G4: DQB8989 | H4: 41260803098929000606570010000715081003657137 | I4: 05094003000155 | J4: COLSON DO BRASIL LTDA | K4: RUA DAS PALMEIRAS 350 | L4: CAPELA VELHA | M4: 002 | N4: ARAUCARIA | O4: PR | P4: 83705-500 | Q4: 05094003000155 | R4: COLSON DO BRASIL LTDA | S4: ARAUCARIA | T4: PR | U4: 05094003000155 | V4: COLSON DO BRASIL LTDA | W4: RUA DAS PALMEIRAS 350 | X4: CAPELA VELHA | Y4: ARAUCARIA | Z4: PR | AA4: (41 ) 38887555 | AC4: 23476033000701 | AD4: BMB MATERIAL DE CONSTRUCAO S.A | AE4: SGN SAO GONACALO | AF4: RJOP | AG4: SAO GONCALO | AH4: RJ | AI4: 23476033000701 | AJ4: BMB MATERIAL DE CONSTRUCAO S.A | AK4: SAO GONCALO | AL4: RJ | AM4: RJO | AN4: 000188531 | AO4: 85.965 | AP4: 0 | AQ4: 7 | AR4: 0 | AS4: CP | AT4: LIQUIDADO | AU4: 46253 | AV4: 452.75 | AW4: 001-DIVERSOS | AX4: 054-PNEUS E CAMARAS DE AR | AY4: 2546.66 | AZ4: COMBINADA | BA4: CO3365267 | BB4: 452.75 | BC4: 398.42 | BD4: 452.75 | BE4: 54.33 | BF4: 0.12 | BG4: 0 | BH4: 85.965 | BI4: 100.2 | BJ4: 0 | BK4: 17 | BL4: 0 | BM4: 9.76 | BN4: 3.82 | BO4: 5.5 | BP4: 3.23 | BQ4: 0 | BR4: 0 | BS4: 0 | BT4: 0 | BU4: 0 | BV4: 0 | BW4: 0 | BX4: 250 | BY4: 0 | BZ4: 0 | CA4: 8.91 | CB4: CTBP | CC4: RJOP | CD4: 383.46 | CE4: 0 | CF4: 0 | CG4: 0 | CH4: 0 | CI4: 0 | CJ4: 0 | CK4: 0 | CN4: 0 | CO4: 0 | CP4: 0 | CQ4: 0 | CR4: 0 | CS4: 0 | CT4: 0 | CU4: 12.89 | CV4: MAPA: 161 | CW4: 0 | CY4: 18 | CZ4: MAPA: 161 | DA4: 0 | DE4: 0 | DF4: A. | DG4: PR | DH4: ARAUCARIA | DI4: 9026067267 | DJ4: (41 ) 38887555 | DK4: 0 | DL4: CTB | DM4: 54.33
A5: 2 | B5: CTB070617-5 | C5: NORMAL | D5: CTBP | E5: CTB | F5: 46237 | G5: DQB8989 | H5: 41260803098929000606570010000715101003657151 | I5: 05094003000155 | J5: COLSON DO BRASIL LTDA | K5: RUA DAS PALMEIRAS 350 | L5: CAPELA VELHA | M5: 002 | N5: ARAUCARIA | O5: PR | P5: 83705-500 | Q5: 05094003000155 | R5: COLSON DO BRASIL LTDA | S5: ARAUCARIA | T5: PR | U5: 05094003000155 | V5: COLSON DO BRASIL LTDA | W5: RUA DAS PALMEIRAS 350 | X5: CAPELA VELHA | Y5: ARAUCARIA | Z5: PR | AA5: (41 ) 38887555 | AC5: 25197980000195 | AD5: TRIUNFO SERVICOS PARA CONSTRUCAO CI | AE5: RIO RIO DE JANEIRO | AF5: RJOP | AG5: RIO DE JANEIRO | AH5: RJ | AI5: 25197980000195 | AJ5: TRIUNFO SERVICOS PARA CONSTRUCAO CI | AK5: RIO DE JANEIRO | AL5: RJ | AM5: RJO | AN5: 000188697 | AO5: 249 | AP5: 0 | AQ5: 15 | AR5: 0 | AS5: CP | AT5: LIQUIDADO | AU5: 46253 | AV5: 334.93 | AW5: 001-DIVERSOS | AX5: 001-DIVERSOS | AY5: 4824.67 | AZ5: COMBINADA | BA5: CO3365267 | BB5: 334.93 | BC5: 294.74 | BD5: 334.93 | BE5: 40.19 | BF5: 0.12 | BG5: 0 | BH5: 249 | BI5: 224.12 | BJ5: 0 | BK5: 17 | BL5: 0 | BM5: 9.76 | BN5: 7.24 | BO5: 16.5 | BP5: 3.23 | BQ5: 0 | BR5: 0 | BS5: 0 | BT5: 0 | BU5: 0 | BV5: 0 | BW5: 0 | BX5: 0 | BY5: 0 | BZ5: 0 | CA5: 16.89 | CB5: CTBP | CC5: RJOP | CD5: 535.2 | CE5: 0 | CF5: 0 | CG5: 0 | CH5: 0 | CI5: 0 | CJ5: 0 | CK5: 0 | CN5: 0 | CO5: 0 | CP5: 0 | CQ5: 0 | CR5: 0 | CS5: 0 | CT5: 0 | CU5: 37.35 | CV5: MAPA: 161 | CW5: 0 | CY5: 44.82 | CZ5: MAPA: 161 | DA5: 0 | DE5: 0 | DF5: A. | DG5: PR | DH5: ARAUCARIA | DI5: 9026067267 | DJ5: (41 ) 38887555 | DK5: 0 | DL5: CTB | DM5: 40.19
A6: 2 | B6: CTB070618-3 | C6: NORMAL | D6: CTBP | E6: CTB | F6: 46237 | G6: DQB8989 | H6: 41260803098929000606570010000715121003657172 | I6: 05094003000155 | J6: COLSON DO BRASIL LTDA | K6: RUA DAS PALMEIRAS 350 | L6: CAPELA VELHA | M6: 002 | N6: ARAUCARIA | O6: PR | P6: 83705-500 | Q6: 05094003000155 | R6: COLSON DO BRASIL LTDA | S6: ARAUCARIA | T6: PR | U6: 05094003000155 | V6: COLSON DO BRASIL LTDA | W6: RUA DAS PALMEIRAS 350 | X6: CAPELA VELHA | Y6: ARAUCARIA | Z6: PR | AA6: (41 ) 38887555 | AC6: 41675052000226 | AD6: NOVA VIANA ALUGUEL DE EQUIPAMENTOS LTDA | AE6: 293 | AF6: EPSI | AG6: VENDA NOVA DO IMIGRANTE | AH6: ES | AI6: 41675052000226 | AJ6: NOVA VIANA ALUGUEL DE EQUIPAMENTOS LTDA | AK6: VENDA NOVA DO IMIGRANTE | AL6: ES | AM6: EPS | AN6: 000188765 | AO6: 106.816 | AP6: 0 | AQ6: 11 | AR6: 0 | AS6: CP | AT6: LIQUIDADO | AU6: 46253 | AV6: 192.94 | AW6: 001-DIVERSOS | AX6: 001-DIVERSOS | AY6: 5881.78 | AZ6: COMBINADA | BA6: CO3365268 | BB6: 192.94 | BC6: 179.43 | BD6: 192.94 | BE6: 13.51 | BF6: 0.07 | BG6: 0 | BH6: 106.816 | BI6: 109.03 | BJ6: 0 | BK6: 17 | BL6: 0 | BM6: 9.76 | BN6: 8.82 | BO6: 11 | BP6: 3.23 | BQ6: 0 | BR6: 0 | BS6: 0 | BT6: 0 | BU6: 0 | BV6: 0 | BW6: 0 | BX6: 0 | BY6: 0 | BZ6: 0 | CA6: 20.59 | CB6: CTBP | CC6: EPSP | CD6: 426.48 | CE6: 0 | CF6: 0 | CG6: 0 | CH6: 0 | CI6: 0 | CJ6: 0 | CK6: 0 | CN6: 0 | CO6: 0 | CP6: 0 | CQ6: 0 | CR6: 0 | CS6: 0 | CT6: 0 | CU6: 16.02 | CV6: MAPA: 161 | CW6: 0 | CY6: 86.13 | CZ6: FATURA: 55156 | DA6: 92.61 | DB6: 055156 | DE6: 0 | DF6: A. | DG6: PR | DH6: ARAUCARIA | DI6: 9026067267 | DJ6: (41 ) 38887555 | DK6: 0 | DL6: CTB | DM6: 13.51
A7: 2 | B7: CTB070619-1 | C7: NORMAL | D7: CTBP | E7: CTB | F7: 46237 | G7: DQB8989 | H7: 41260803098929000606570010000715161003657210 | I7: 05094003000155 | J7: COLSON DO BRASIL LTDA | K7: RUA DAS PALMEIRAS 350 | L7: CAPELA VELHA | M7: 002 | N7: ARAUCARIA | O7: PR | P7: 83705-500 | Q7: 05094003000155 | R7: COLSON DO BRASIL LTDA | S7: ARAUCARIA | T7: PR | U7: 05094003000155 | V7: COLSON DO BRASIL LTDA | W7: RUA DAS PALMEIRAS 350 | X7: CAPELA VELHA | Y7: ARAUCARIA | Z7: PR | AA7: (41 ) 38887555 | AC7: 08696745000149 | AD7: JP COMERCIO DE FERRAGENS PARA MOVEIS LTDA | AE7: 365 | AF7: TAMR | AG7: UBA | AH7: MG | AI7: 08696745000149 | AJ7: JP COMERCIO DE FERRAGENS PARA MOVEIS LTDA | AK7: UBA | AL7: MG | AM7: TAM | AN7: 000188760 | AO7: 7.945 | AP7: 0.4856 | AQ7: 1 | AR7: 0 | AS7: CP | AT7: LIQUIDADO | AU7: 46253 | AV7: 219.59 | AW7: 001-DIVERSOS | AX7: 001-DIVERSOS | AY7: 303.14 | AZ7: COMBINADA | BA7: CO3365280 | BB7: 219.59 | BC7: 193.24 | BD7: 219.59 | BE7: 26.35 | BF7: 0.12 | BG7: 0 | BH7: 145.68 | BI7: 148.94 | BJ7: 0 | BK7: 17 | BL7: 0 | BM7: 9.76 | BN7: 2.25 | BO7: 11 | BP7: 3.23 | BQ7: 0 | BR7: 0 | BS7: 0 | BT7: 0 | BU7: 0 | BV7: 0 | BW7: 0 | BX7: 0 | BY7: 0 | BZ7: 0 | CA7: 1.06 | CB7: CTBP | CC7: TAMR | CD7: 361.05 | CE7: 0 | CF7: 0 | CG7: 0 | CH7: 0 | CI7: 0 | CJ7: 0 | CK7: 0 | CN7: 0 | CO7: 0 | CP7: 0 | CQ7: 0 | CR7: 0 | CS7: 0 | CT7: 0 | CU7: 12 | CV7: MAPA: 161 | CW7: 0 | CY7: 72.84 | CZ7: MAPA: 0 | DA7: =CY7 -> 72.84 | DE7: 0 | DF7: A. | DG7: PR | DH7: ARAUCARIA | DI7: 9026067267 | DJ7: (41 ) 38887555 | DK7: 0 | DL7: CTB | DM7: 26.35
A8: 2 | B8: CTB070620-5 | C8: NORMAL | D8: CTBP | E8: CTB | F8: 46237 | G8: DQB8989 | H8: 41260803098929000606570010000715181003657230 | I8: 05094003000155 | J8: COLSON DO BRASIL LTDA | K8: RUA DAS PALMEIRAS 350 | L8: CAPELA VELHA | M8: 002 | N8: ARAUCARIA | O8: PR | P8: 83705-500 | Q8: 05094003000155 | R8: COLSON DO BRASIL LTDA | S8: ARAUCARIA | T8: PR | U8: 05094003000155 | V8: COLSON DO BRASIL LTDA | W8: RUA DAS PALMEIRAS 350 | X8: CAPELA VELHA | Y8: ARAUCARIA | Z8: PR | AA8: (41 ) 38887555 | AC8: 55171639000121 | AD8: TS LASER LOCACAO DE EQUIPAMENTOS LT | AE8: 06 ZONA SUL | AF8: SPOP | AG8: SAO PAULO | AH8: SP | AI8: 55171639000121 | AJ8: TS LASER LOCACAO DE EQUIPAMENTOS LT | AK8: SAO PAULO | AL8: SP | AM8: SPO | AN8: 000188767 | AO8: 11.35 | AP8: 0 | AQ8: 2 | AR8: 0 | AS8: CP | AT8: LIQUIDADO | AU8: 46253 | AV8: 95.18 | AW8: 001-DIVERSOS | AX8: 001-DIVERSOS | AY8: 1713.74 | AZ8: COMBINADA | BA8: CO3365274 | BB8: 95.18 | BC8: 83.76 | BD8: 95.18 | BE8: 11.42 | BF8: 0.12 | BG8: 0 | BH8: 11.35 | BI8: 39.7 | BJ8: 0 | BK8: 17 | BL8: 0 | BM8: 9.76 | BN8: 2.57 | BO8: 5.5 | BP8: 3.23 | BQ8: 0 | BR8: 0 | BS8: 0 | BT8: 0 | BU8: 0 | BV8: 0 | BW8: 0 | BX8: 0 | BY8: 0 | BZ8: 0 | CA8: 6 | CB8: CTBP | CC8: SPOP | CD8: 375.17 | CE8: 0 | CF8: 0 | CG8: 0 | CH8: 0 | CI8: 0 | CJ8: 0 | CK8: 0 | CN8: 0 | CO8: 0 | CP8: 0 | CQ8: 0 | CR8: 0 | CS8: 0 | CT8: 0 | CU8: 12 | CV8: MAPA: 161 | CW8: 0 | CY8: 18 | CZ8: MAPA: 161 | DA8: 0 | DE8: 0 | DF8: A. | DG8: PR | DH8: ARAUCARIA | DI8: 9026067267 | DJ8: (41 ) 38887555 | DK8: 0 | DL8: CTB | DM8: 11.42
A9: 2 | B9: CTB070621-3 | C9: NORMAL | D9: CTBP | E9: CTB | F9: 46237 | G9: DQB8989 | H9: 41260803098929000606570010000715091003657142 | I9: 05094003000155 | J9: COLSON DO BRASIL LTDA | K9: RUA DAS PALMEIRAS 350 | L9: CAPELA VELHA | M9: 002 | N9: ARAUCARIA | O9: PR | P9: 83705-500 | Q9: 05094003000155 | R9: COLSON DO BRASIL LTDA | S9: ARAUCARIA | T9: PR | U9: 05094003000155 | V9: COLSON DO BRASIL LTDA | W9: RUA DAS PALMEIRAS 350 | X9: CAPELA VELHA | Y9: ARAUCARIA | Z9: PR | AA9: (41 ) 38887555 | AC9: 04956134000131 | AD9: RODAS E RODIZIOS LTDA | AE9: 005 CONTAGEM | AF9: BHZP | AG9: CONTAGEM | AH9: MG | AI9: 04956134000131 | AJ9: RODAS E RODIZIOS LTDA | AK9: CONTAGEM | AL9: MG | AM9: BHZ | AN9: 000188705 | AO9: 83.37 | AP9: 0 | AQ9: 7 | AR9: 0 | AS9: CP | AT9: LIQUIDADO | AU9: 46253 | AV9: 177.52 | AW9: 001-DIVERSOS | AX9: 001-DIVERSOS | AY9: 3905.33 | AZ9: COMBINADA | BA9: CO3365271 | BB9: 177.52 | BC9: 156.22 | BD9: 177.52 | BE9: 21.3 | BF9: 0.12 | BG9: 0 | BH9: 83.37 | BI9: 101.2 | BJ9: 0 | BK9: 17 | BL9: 0 | BM9: 9.76 | BN9: 5.86 | BO9: 5.5 | BP9: 3.23 | BQ9: 0 | BR9: 0 | BS9: 0 | BT9: 0 | BU9: 0 | BV9: 0 | BW9: 0 | BX9: 0 | BY9: 0 | BZ9: 0 | CA9: 13.67 | CB9: CTBP | CC9: BHZP | CD9: 400.72 | CE9: 0 | CF9: 0 | CG9: 0 | CH9: 0 | CI9: 0 | CJ9: 0 | CK9: 0 | CN9: 0 | CO9: 0 | CP9: 0 | CQ9: 0 | CR9: 0 | CS9: 0 | CT9: 0 | CU9: 12.51 | CV9: MAPA: 161 | CW9: 0 | CY9: 15 | CZ9: MAPA: 161 | DA9: 0 | DE9: 0 | DF9: A. | DG9: PR | DH9: ARAUCARIA | DI9: 9026067267 | DJ9: (41 ) 38887555 | DK9: 0 | DL9: CTB | DM9: 21.3
A10: 2 | B10: CTB070622-1 | C10: NORMAL | D10: CTBP | E10: CTB | F10: 46237 | G10: DQB8989 | H10: 41260803098929000606570010000715201003657255 | I10: 05094003000155 | J10: COLSON DO BRASIL LTDA | K10: RUA DAS PALMEIRAS 350 | L10: CAPELA VELHA | M10: 002 | N10: ARAUCARIA | O10: PR | P10: 83705-500 | Q10: 05094003000155 | R10: COLSON DO BRASIL LTDA | S10: ARAUCARIA | T10: PR | U10: 05094003000155 | V10: COLSON DO BRASIL LTDA | W10: RUA DAS PALMEIRAS 350 | X10: CAPELA VELHA | Y10: ARAUCARIA | Z10: PR | AA10: (41 ) 38887555 | AC10: 23476033001260 | AD10: BMB MATERIAL DE CONSTRUCAO S.A. | AE10: 09 GR2 | AF10: SPOP | AG10: SUZANO | AH10: SP | AI10: 23476033001260 | AJ10: BMB MATERIAL DE CONSTRUCAO S.A. | AK10: SUZANO | AL10: SP | AM10: SPO | AN10: 000187858 | AO10: 39.4 | AP10: 0 | AQ10: 4 | AR10: 0 | AS10: CP | AT10: LIQUIDADO | AU10: 46253 | AV10: 397 | AW10: 001-DIVERSOS | AX10: 001-DIVERSOS | AY10: 1375.97 | AZ10: COMBINADA | BA10: CO3365274 | BB10: 397 | BC10: 349.36 | BD10: 397 | BE10: 47.64 | BF10: 0.12 | BG10: 0 | BH10: 39.4 | BI10: 56.8 | BJ10: 0 | BK10: 17 | BL10: 0 | BM10: 9.76 | BN10: 2.25 | BO10: 5.5 | BP10: 3.23 | BQ10: 0 | BR10: 0 | BS10: 0 | BT10: 0 | BU10: 0 | BV10: 0 | BW10: 0 | BX10: 250 | BY10: 0 | BZ10: 0 | CA10: 4.82 | CB10: CTBP | CC10: SPOP | CD10: 371.76 | CE10: 0 | CF10: 0 | CG10: 0 | CH10: 0 | CI10: 0 | CJ10: 0 | CK10: 0 | CN10: 0 | CO10: 0 | CP10: 0 | CQ10: 0 | CR10: 0 | CS10: 0 | CT10: 0 | CU10: 12 | CV10: MAPA: 161 | CW10: 0 | CY10: 18 | CZ10: MAPA: 161 | DA10: 0 | DE10: 0 | DF10: A. | DG10: PR | DH10: ARAUCARIA | DI10: 9026067267 | DJ10: (41 ) 38887555 | DK10: 0 | DL10: CTB | DM10: 47.64
A11: 2 | B11: CTB070623-0 | C11: NORMAL | D11: CTBP | E11: CTB | F11: 46237 | G11: DQB8989 | H11: 41260803098929000606570010000715111003657167 | I11: 05094003000155 | J11: COLSON DO BRASIL LTDA | K11: RUA DAS PALMEIRAS 350 | L11: CAPELA VELHA | M11: 002 | N11: ARAUCARIA | O11: PR | P11: 83705-500 | Q11: 05094003000155 | R11: COLSON DO BRASIL LTDA | S11: ARAUCARIA | T11: PR | U11: 05094003000155 | V11: COLSON DO BRASIL LTDA | W11: RUA DAS PALMEIRAS 350 | X11: CAPELA VELHA | Y11: ARAUCARIA | Z11: PR | AA11: (41 ) 38887555 | AC11: 23476033001856 | AD11: BMB MATERIAL DE CONSTRUCAO S.A. 0018-56 | AE11: CAX DUQUE DE CAXIAS | AF11: RJOP | AG11: DUQUE DE CAXIAS | AH11: RJ | AI11: 23476033001856 | AJ11: BMB MATERIAL DE CONSTRUCAO S.A. 0018-56 | AK11: DUQUE DE CAXIAS | AL11: RJ | AM11: RJO | AN11: 000188526 | AO11: 55.6 | AP11: 0 | AQ11: 9 | AR11: 0 | AS11: CP | AT11: LIQUIDADO | AU11: 46253 | AV11: 429.09 | AW11: 001-DIVERSOS | AX11: 001-DIVERSOS | AY11: 1903.24 | AZ11: COMBINADA | BA11: CO3365267 | BB11: 429.09 | BC11: 377.6 | BD11: 429.09 | BE11: 51.49 | BF11: 0.12 | BG11: 0 | BH11: 55.6 | BI11: 82.6 | BJ11: 0 | BK11: 17 | BL11: 0 | BM11: 9.76 | BN11: 2.85 | BO11: 5.5 | BP11: 3.23 | BQ11: 0 | BR11: 0 | BS11: 0 | BT11: 0 | BU11: 0 | BV11: 0 | BW11: 0 | BX11: 250 | BY11: 0 | BZ11: 0 | CA11: 6.66 | CB11: CTBP | CC11: RJOP | CD11: 377.02 | CE11: 0 | CF11: 0 | CG11: 0 | CH11: 0 | CI11: 0 | CJ11: 0 | CK11: 0 | CN11: 0 | CO11: 0 | CP11: 0 | CQ11: 0 | CR11: 0 | CS11: 0 | CT11: 0 | CU11: 12 | CV11: MAPA: 161 | CW11: 0 | CY11: 18 | CZ11: MAPA: 161 | DA11: 0 | DE11: 0 | DF11: A. | DG11: PR | DH11: ARAUCARIA | DI11: 9026067267 | DJ11: (41 ) 38887555 | DK11: 0 | DL11: CTB | DM11: 51.49
A12: 2 | B12: CTB070708-2 | C12: NORMAL | D12: CTBP | E12: CTB | F12: 46238 | G12: DQB8989 | H12: 41260803098929000606570010000716041003663389 | I12: 05094003000155 | J12: COLSON DO BRASIL LTDA | K12: RUA DAS PALMEIRAS 350 | L12: CAPELA VELHA | M12: 002 | N12: ARAUCARIA | O12: PR | P12: 83705-500 | Q12: 05094003000155 | R12: COLSON DO BRASIL LTDA | S12: ARAUCARIA | T12: PR | U12: 05094003000155 | V12: COLSON DO BRASIL LTDA | W12: RUA DAS PALMEIRAS 350 | X12: CAPELA VELHA | Y12: ARAUCARIA | Z12: PR | AA12: (41 ) 38887555 | AC12: 10918072000176 | AD12: LUZ MAR MADEIRAS LTDA 12007391 | AE12: RIO RIO DE JANEIRO | AF12: RJOP | AG12: RIO DE JANEIRO | AH12: RJ | AI12: 10918072000176 | AJ12: LUZ MAR MADEIRAS LTDA 12007391 | AK12: RIO DE JANEIRO | AL12: RJ | AM12: RJO | AN12: 000188840 | AO12: 125.756 | AP12: 0 | AQ12: 13 | AR12: 0 | AS12: CP | AT12: LIQUIDADO | AU12: 46253 | AV12: 196.3 | AW12: 001-DIVERSOS | AX12: 001-DIVERSOS | AY12: 3711.94 | AZ12: COMBINADA | BA12: CO3365267 | BB12: 196.3 | BC12: 172.74 | BD12: 196.3 | BE12: 23.56 | BF12: 0.12 | BG12: 0 | BH12: 125.756 | BI12: 113.19 | BJ12: 0 | BK12: 17 | BL12: 0 | BM12: 9.76 | BN12: 5.57 | BO12: 11 | BP12: 3.23 | BQ12: 0 | BR12: 0 | BS12: 0 | BT12: 0 | BU12: 0 | BV12: 0 | BW12: 0 | BX12: 0 | BY12: 0 | BZ12: 0 | CA12: 12.99 | CB12: CTBP | CC12: RJOP | CD12: 398.26 | CE12: 0 | CF12: 0 | CG12: 0 | CH12: 0 | CI12: 0 | CJ12: 0 | CK12: 0 | CN12: 0 | CO12: 0 | CP12: 0 | CQ12: 0 | CR12: 0 | CS12: 0 | CT12: 0 | CU12: 18.86 | CV12: MAPA: 161 | CW12: 0 | CY12: 22.64 | CZ12: MAPA: 161 | DA12: 0 | DE12: 0 | DF12: A. | DG12: PR | DH12: ARAUCARIA | DI12: 9026067267 | DJ12: (41 ) 38887555 | DK12: 0 | DL12: CTB | DM12: 23.56
A13: 2 | B13: CTB070709-1 | C13: NORMAL | D13: CTBP | E13: CTB | F13: 46238 | G13: DQB8989 | H13: 41260803098929000606570010000716051003663408 | I13: 05094003000155 | J13: COLSON DO BRASIL LTDA | K13: RUA DAS PALMEIRAS 350 | L13: CAPELA VELHA | M13: 002 | N13: ARAUCARIA | O13: PR | P13: 83705-500 | Q13: 05094003000155 | R13: COLSON DO BRASIL LTDA | S13: ARAUCARIA | T13: PR | U13: 05094003000155 | V13: COLSON DO BRASIL LTDA | W13: RUA DAS PALMEIRAS 350 | X13: CAPELA VELHA | Y13: ARAUCARIA | Z13: PR | AA13: (41 ) 38887555 | AC13: 66294976000122 | AD13: JD COM DE DERIVADOS DE BORRACH | AE13: 384 | AF13: TRUP | AG13: UBERLANDIA | AH13: MG | AI13: 66294976000122 | AJ13: JD COM DE DERIVADOS DE BORRACH | AK13: UBERLANDIA | AL13: MG | AM13: TRU | AN13: 000188806 | AO13: 235.713 | AP13: 0 | AQ13: 19 | AR13: 0 | AS13: CP | AT13: LIQUIDADO | AU13: 46253 | AV13: 422.6 | AW13: 001-DIVERSOS | AX13: 054-PNEUS E CAMARAS DE AR | AY13: 8494.14 | AZ13: COMBINADA | BA13: CO3365284 | BB13: 422.6 | BC13: 371.89 | BD13: 422.6 | BE13: 50.71 | BF13: 0.12 | BG13: 0 | BH13: 235.713 | BI13: 282.93 | BJ13: 0 | BK13: 17 | BL13: 0 | BM13: 9.76 | BN13: 12.74 | BO13: 16.5 | BP13: 3.23 | BQ13: 0 | BR13: 0 | BS13: 0 | BT13: 0 | BU13: 0 | BV13: 0 | BW13: 0 | BX13: 0 | BY13: 0 | BZ13: 0 | CA13: 29.73 | CB13: CTBP | CC13: PANI | CD13: 549.69 | CE13: 0 | CF13: 0 | CG13: 0 | CH13: 0 | CI13: 0 | CJ13: 0 | CK13: 0 | CN13: 0 | CO13: 0 | CP13: 0 | CQ13: 0 | CR13: 0 | CS13: 0 | CT13: 0 | CU13: 35.36 | CV13: MAPA: 161 | CW13: 0 | CY13: 169.04 | CZ13: FATURA: 232309 | DA13: 161.4 | DB13: 232309 | DE13: 0 | DF13: A. | DG13: PR | DH13: ARAUCARIA | DI13: 9026067267 | DJ13: (41 ) 38887555 | DK13: 0 | DL13: CTB | DM13: 50.71
A14: 2 | B14: CTB070710-4 | C14: NORMAL | D14: CTBP | E14: CTB | F14: 46238 | G14: DQB8989 | H14: 41260803098929000606570010000716061003663421 | I14: 05094003000155 | J14: COLSON DO BRASIL LTDA | K14: RUA DAS PALMEIRAS 350 | L14: CAPELA VELHA | M14: 002 | N14: ARAUCARIA | O14: PR | P14: 83705-500 | Q14: 05094003000155 | R14: COLSON DO BRASIL LTDA | S14: ARAUCARIA | T14: PR | U14: 05094003000155 | V14: COLSON DO BRASIL LTDA | W14: RUA DAS PALMEIRAS 350 | X14: CAPELA VELHA | Y14: ARAUCARIA | Z14: PR | AA14: (41 ) 38887555 | AC14: 22860350000160 | AD14: LEONILDO DA CRUZ SANTANA 11590235657 | AE14: 395 | AF14: VEAI | AG14: RIO PARDO DE MINAS | AH14: MG | AI14: 22860350000160 | AJ14: LEONILDO DA CRUZ SANTANA 11590235657 | AK14: RIO PARDO DE MINAS | AL14: MG | AM14: VEA | AN14: 000188808 | AO14: 210.65 | AP14: 0 | AQ14: 17 | AR14: 0 | AS14: CP | AT14: LIQUIDADO | AU14: 46253 | AV14: 375.43 | AW14: 001-DIVERSOS | AX14: 001-DIVERSOS | AY14: 6209.05 | AZ14: COMBINADA | BA14: CO3365293 | BB14: 375.43 | BC14: 330.38 | BD14: 375.43 | BE14: 45.05 | BF14: 0.12 | BG14: 0 | BH14: 210.65 | BI14: 252.85 | BJ14: 0 | BK14: 17 | BL14: 0 | BM14: 9.76 | BN14: 9.31 | BO14: 16.5 | BP14: 3.23 | BQ14: 0 | BR14: 0 | BS14: 0 | BT14: 0 | BU14: 0 | BV14: 0 | BW14: 0 | BX14: 0 | BY14: 0 | BZ14: 0 | CA14: 21.73 | CB14: CTBP | CC14: RMCP | CD14: 457.34 | CE14: 0 | CF14: 0 | CG14: 0 | CH14: 0 | CI14: 0 | CJ14: 0 | CK14: 0 | CN14: 0 | CO14: 0 | CP14: 0 | CQ14: 0 | CR14: 0 | CS14: 0 | CT14: 0 | CU14: 31.6 | CV14: MAPA: 161 | CW14: 0 | CY14: 112.63 | CZ14: MAPA: 0 | DA14: =CY14 -> 112.63 | DE14: 0 | DF14: A. | DG14: PR | DH14: ARAUCARIA | DI14: 9026067267 | DJ14: (41 ) 38887555 | DK14: 0 | DL14: CTB | DM14: 45.05
A15: 2 | B15: CTB070711-2 | C15: NORMAL | D15: CTBP | E15: CTB | F15: 46238 | G15: DQB8989 | H15: 41260803098929000606570010000716071003663445 | I15: 05094003000155 | J15: COLSON DO BRASIL LTDA | K15: RUA DAS PALMEIRAS 350 | L15: CAPELA VELHA | M15: 002 | N15: ARAUCARIA | O15: PR | P15: 83705-500 | Q15: 05094003000155 | R15: COLSON DO BRASIL LTDA | S15: ARAUCARIA | T15: PR | U15: 05094003000155 | V15: COLSON DO BRASIL LTDA | W15: RUA DAS PALMEIRAS 350 | X15: CAPELA VELHA | Y15: ARAUCARIA | Z15: PR | AA15: (41 ) 38887555 | AC15: 03047584000149 | AD15: IMPERIO DOS ROLAMENTOS E PECAS | AE15: 256 | AF15: MVGP | AG15: PETROPOLIS | AH15: RJ | AI15: 03047584000149 | AJ15: IMPERIO DOS ROLAMENTOS E PECAS | AK15: PETROPOLIS | AL15: RJ | AM15: MVG | AN15: 000188845 | AO15: 80.92 | AP15: 0 | AQ15: 10 | AR15: 0 | AS15: CP | AT15: LIQUIDADO | AU15: 46253 | AV15: 210.13 | AW15: 001-DIVERSOS | AX15: 001-DIVERSOS | AY15: 3835.45 | AZ15: COMBINADA | BA15: CO3365270 | BB15: 210.13 | BC15: 184.91 | BD15: 210.13 | BE15: 25.22 | BF15: 0.12 | BG15: 0 | BH15: 80.92 | BI15: 130.25 | BJ15: 0 | BK15: 17 | BL15: 0 | BM15: 9.76 | BN15: 5.75 | BO15: 5.5 | BP15: 3.23 | BQ15: 0 | BR15: 0 | BS15: 0 | BT15: 0 | BU15: 0 | BV15: 0 | BW15: 0 | BX15: 0 | BY15: 0 | BZ15: 0 | CA15: 13.42 | CB15: CTBP | CC15: ITAI | CD15: 399.87 | CE15: 0 | CF15: 0 | CG15: 0 | CH15: 0 | CI15: 0 | CJ15: 0 | CK15: 0 | CN15: 0 | CO15: 0 | CP15: 0 | CQ15: 0 | CR15: 0 | CS15: 0 | CT15: 0 | CU15: 12.14 | CV15: MAPA: 161 | CW15: 0 | CY15: 68.82 | CZ15: FATURA: 17774 | DA15: 68.82 | DB15: 017774 | DE15: 0 | DF15: A. | DG15: PR | DH15: ARAUCARIA | DI15: 9026067267 | DJ15: (41 ) 38887555 | DK15: 0 | DL15: CTB | DM15: 25.22
A16: 2 | B16: CTB070712-1 | C16: NORMAL | D16: CTBP | E16: CTB | F16: 46238 | G16: DQB8989 | H16: 41260803098929000606570010000716081003663469 | I16: 05094003000155 | J16: COLSON DO BRASIL LTDA | K16: RUA DAS PALMEIRAS 350 | L16: CAPELA VELHA | M16: 002 | N16: ARAUCARIA | O16: PR | P16: 83705-500 | Q16: 05094003000155 | R16: COLSON DO BRASIL LTDA | S16: ARAUCARIA | T16: PR | U16: 05094003000155 | V16: COLSON DO BRASIL LTDA | W16: RUA DAS PALMEIRAS 350 | X16: CAPELA VELHA | Y16: ARAUCARIA | Z16: PR | AA16: (41 ) 38887555 | AC16: 08949409000160 | AD16: CONCERPLAN COMERCIO DE ALIMENTOS EI | AE16: 133 | AF16: PSPP | AG16: INDAIATUBA | AH16: SP | AI16: 08949409000160 | AJ16: CONCERPLAN COMERCIO DE ALIMENTOS EI | AK16: INDAIATUBA | AL16: SP | AM16: PSP | AN16: 000188788 | AO16: 29.48 | AP16: 0 | AQ16: 5 | AR16: 0 | AS16: CP | AT16: LIQUIDADO | AU16: 46253 | AV16: 166.34 | AW16: 001-DIVERSOS | AX16: 001-DIVERSOS | AY16: 5585.62 | AZ16: COMBINADA | BA16: CO3365266 | BB16: 166.34 | BC16: 146.38 | BD16: 166.34 | BE16: 19.96 | BF16: 0.12 | BG16: 0 | BH16: 29.48 | BI16: 82.96 | BJ16: 0 | BK16: 17 | BL16: 0 | BM16: 9.76 | BN16: 8.38 | BO16: 5.5 | BP16: 3.23 | BQ16: 0 | BR16: 0 | BS16: 0 | BT16: 0 | BU16: 0 | BV16: 0 | BW16: 0 | BX16: 0 | BY16: 0 | BZ16: 0 | CA16: 19.55 | CB16: CTBP | CC16: SPOR | CD16: 422.61 | CE16: 0 | CF16: 0 | CG16: 0 | CH16: 0 | CI16: 0 | CJ16: 0 | CK16: 0 | CN16: 0 | CO16: 0 | CP16: 0 | CQ16: 0 | CR16: 0 | CS16: 0 | CT16: 0 | CU16: 12 | CV16: MAPA: 161 | CW16: 0 | CY16: 49.5 | CZ16: MAPA: 161 | DA16: =CY16 -> 49.5 | DE16: 0 | DF16: A. | DG16: PR | DH16: ARAUCARIA | DI16: 9026067267 | DJ16: (41 ) 38887555 | DK16: 0 | DL16: CTB | DM16: 19.96
A17: 2 | B17: CTB070713-9 | C17: NORMAL | D17: CTBP | E17: CTB | F17: 46238 | G17: DQB8989 | H17: 41260803098929000606570010000716091003663474 | I17: 05094003000155 | J17: COLSON DO BRASIL LTDA | K17: RUA DAS PALMEIRAS 350 | L17: CAPELA VELHA | M17: 002 | N17: ARAUCARIA | O17: PR | P17: 83705-500 | Q17: 05094003000155 | R17: COLSON DO BRASIL LTDA | S17: ARAUCARIA | T17: PR | U17: 05094003000155 | V17: COLSON DO BRASIL LTDA | W17: RUA DAS PALMEIRAS 350 | X17: CAPELA VELHA | Y17: ARAUCARIA | Z17: PR | AA17: (41 ) 38887555 | AC17: 01093975000174 | AD17: OMNITEK TECNOLOGIA LTDA. | AE17: 07 ZONA OESTE | AF17: SPOP | AG17: SAO PAULO | AH17: SP | AI17: 01093975000174 | AJ17: OMNITEK TECNOLOGIA LTDA. | AK17: SAO PAULO | AL17: SP | AM17: SPO | AN17: 000188778 | AO17: 35 | AP17: 0 | AQ17: 3 | AR17: 0 | AS17: CP | AT17: LIQUIDADO | AU17: 46253 | AV17: 396.82 | AW17: 001-DIVERSOS | AX17: 001-DIVERSOS | AY17: 1332.17 | AZ17: COMBINADA | BA17: CO3365274 | BB17: 396.82 | BC17: 349.2 | BD17: 396.82 | BE17: 47.62 | BF17: 0.12 | BG17: 0 | BH17: 35 | BI17: 56.8 | BJ17: 0 | BK17: 17 | BL17: 0 | BM17: 9.76 | BN17: 2.25 | BO17: 5.5 | BP17: 3.23 | BQ17: 0 | BR17: 0 | BS17: 0 | BT17: 0 | BU17: 0 | BV17: 0 | BW17: 0 | BX17: 250 | BY17: 0 | BZ17: 0 | CA17: 4.66 | CB17: CTBP | CC17: SPOP | CD17: 371.31 | CE17: 0 | CF17: 0 | CG17: 0 | CH17: 0 | CI17: 0 | CJ17: 0 | CK17: 0 | CN17: 0 | CO17: 0 | CP17: 0 | CQ17: 0 | CR17: 0 | CS17: 0 | CT17: 0 | CU17: 12 | CV17: MAPA: 161 | CW17: 0 | CY17: 18 | CZ17: MAPA: 161 | DA17: 0 | DE17: 0 | DF17: A. | DG17: PR | DH17: ARAUCARIA | DI17: 9026067267 | DJ17: (41 ) 38887555 | DK17: 0 | DL17: CTB | DM17: 47.62
A18: 2 | B18: CTB070714-7 | C18: NORMAL | D18: CTBP | E18: CTB | F18: 46238 | G18: DQB8989 | H18: 41260803098929000606570010000716101003663491 | I18: 05094003000155 | J18: COLSON DO BRASIL LTDA | K18: RUA DAS PALMEIRAS 350 | L18: CAPELA VELHA | M18: 002 | N18: ARAUCARIA | O18: PR | P18: 83705-500 | Q18: 05094003000155 | R18: COLSON DO BRASIL LTDA | S18: ARAUCARIA | T18: PR | U18: 05094003000155 | V18: COLSON DO BRASIL LTDA | W18: RUA DAS PALMEIRAS 350 | X18: CAPELA VELHA | Y18: ARAUCARIA | Z18: PR | AA18: (41 ) 38887555 | AC18: 31555733000116 | AD18: SARGENTO FERRAGENS LTDA | AE18: CAX DUQUE DE CAXIAS | AF18: RJOP | AG18: DUQUE DE CAXIAS | AH18: RJ | AI18: 31555733000116 | AJ18: SARGENTO FERRAGENS LTDA | AK18: DUQUE DE CAXIAS | AL18: RJ | AM18: RJO | AN18: 000188799 | AO18: 148.6 | AP18: 0 | AQ18: 15 | AR18: 0 | AS18: CP | AT18: LIQUIDADO | AU18: 46253 | AV18: 513.05 | AW18: 001-DIVERSOS | AX18: 001-DIVERSOS | AY18: 5349.3 | AZ18: COMBINADA | BA18: CO3365267 | BB18: 513.05 | BC18: 451.48 | BD18: 513.05 | BE18: 61.57 | BF18: 0.12 | BG18: 0 | BH18: 148.6 | BI18: 133.75 | BJ18: 0 | BK18: 17 | BL18: 0 | BM18: 9.76 | BN18: 8.02 | BO18: 11 | BP18: 3.23 | BQ18: 0 | BR18: 0 | BS18: 0 | BT18: 0 | BU18: 0 | BV18: 0 | BW18: 0 | BX18: 250 | BY18: 0 | BZ18: 0 | CA18: 18.72 | CB18: CTBP | CC18: RJOP | CD18: 419.54 | CE18: 0 | CF18: 0 | CG18: 0 | CH18: 0 | CI18: 0 | CJ18: 0 | CK18: 0 | CN18: 0 | CO18: 0 | CP18: 0 | CQ18: 0 | CR18: 0 | CS18: 0 | CT18: 0 | CU18: 22.29 | CV18: MAPA: 161 | CW18: 0 | CY18: 26.75 | CZ18: MAPA: 161 | DA18: 0 | DE18: 0 | DF18: A. | DG18: PR | DH18: ARAUCARIA | DI18: 9026067267 | DJ18: (41 ) 38887555 | DK18: 0 | DL18: CTB | DM18: 61.57
A19: 2 | B19: CTB070715-5 | C19: NORMAL | D19: CTBP | E19: CTB | F19: 46238 | G19: DQB8989 | H19: 41260803098929000606570010000716111003663510 | I19: 05094003000155 | J19: COLSON DO BRASIL LTDA | K19: RUA DAS PALMEIRAS 350 | L19: CAPELA VELHA | M19: 002 | N19: ARAUCARIA | O19: PR | P19: 83705-500 | Q19: 05094003000155 | R19: COLSON DO BRASIL LTDA | S19: ARAUCARIA | T19: PR | U19: 05094003000155 | V19: COLSON DO BRASIL LTDA | W19: RUA DAS PALMEIRAS 350 | X19: CAPELA VELHA | Y19: ARAUCARIA | Z19: PR | AA19: (41 ) 38887555 | AC19: 00373798000117 | AD19: OPCAO PARAFUSOS E FERRAMENTAS LTDA - EPP | AE19: 299 | AF19: EPSI | AG19: SAO MATEUS | AH19: ES | AI19: 00373798000117 | AJ19: OPCAO PARAFUSOS E FERRAMENTAS LTDA - EPP | AK19: SAO MATEUS | AL19: ES | AM19: EPS | AN19: 000188844 | AO19: 315.27 | AP19: 0 | AQ19: 39 | AR19: 0 | AS19: CP | AT19: LIQUIDADO | AU19: 46253 | AV19: 463.4 | AW19: 001-DIVERSOS | AX19: 001-DIVERSOS | AY19: 11435.48 | AZ19: COMBINADA | BA19: CO3365268 | BB19: 463.4 | BC19: 430.96 | BD19: 463.4 | BE19: 32.44 | BF19: 0.07 | BG19: 0 | BH19: 315.27 | BI19: 321.8 | BJ19: 0 | BK19: 17 | BL19: 0 | BM19: 9.76 | BN19: 17.15 | BO19: 22 | BP19: 3.23 | BQ19: 0 | BR19: 0 | BS19: 0 | BT19: 0 | BU19: 0 | BV19: 0 | BW19: 0 | BX19: 0 | BY19: 0 | BZ19: 0 | CA19: 40.02 | CB19: CTBP | CC19: EPSP | CD19: 786.89 | CE19: 0 | CF19: 0 | CG19: 0 | CH19: 0 | CI19: 0 | CJ19: 0 | CK19: 0 | CN19: 0 | CO19: 0 | CP19: 0 | CQ19: 0 | CR19: 0 | CS19: 0 | CT19: 0 | CU19: 47.29 | CV19: MAPA: 161 | CW19: 0 | CY19: 206.86 | CZ19: FATURA: 55181 | DA19: 222.43 | DB19: 055181 | DE19: 0 | DF19: A. | DG19: PR | DH19: ARAUCARIA | DI19: 9026067267 | DJ19: (41 ) 38887555 | DK19: 0 | DL19: CTB | DM19: 32.44
A20: 2 | B20: CTB070716-3 | C20: NORMAL | D20: CTBP | E20: CTB | F20: 46238 | G20: DQB8989 | H20: 41260803098929000606570010000716121003663534 | I20: 05094003000155 | J20: COLSON DO BRASIL LTDA | K20: RUA DAS PALMEIRAS 350 | L20: CAPELA VELHA | M20: 002 | N20: ARAUCARIA | O20: PR | P20: 83705-500 | Q20: 05094003000155 | R20: COLSON DO BRASIL LTDA | S20: ARAUCARIA | T20: PR | U20: 05094003000155 | V20: COLSON DO BRASIL LTDA | W20: RUA DAS PALMEIRAS 350 | X20: CAPELA VELHA | Y20: ARAUCARIA | Z20: PR | AA20: (41 ) 38887555 | AC20: 23476033000531 | AD20: BMB MATERIAL DE CONSTRUCAO S.A | AE20: RIO RIO DE JANEIRO | AF20: RJOP | AG20: RIO DE JANEIRO | AH20: RJ | AI20: 23476033000531 | AJ20: BMB MATERIAL DE CONSTRUCAO S.A | AK20: RIO DE JANEIRO | AL20: RJ | AM20: RJO | AN20: 000188726 | AO20: 84.03 | AP20: 0 | AQ20: 9 | AR20: 0 | AS20: CP | AT20: LIQUIDADO | AU20: 46253 | AV20: 452.1 | AW20: 001-DIVERSOS | AX20: 001-DIVERSOS | AY20: 2430.21 | AZ20: COMBINADA | BA20: CO3365267 | BB20: 452.1 | BC20: 397.85 | BD20: 452.1 | BE20: 54.25 | BF20: 0.12 | BG20: 0 | BH20: 84.03 | BI20: 100.2 | BJ20: 0 | BK20: 17 | BL20: 0 | BM20: 9.76 | BN20: 3.65 | BO20: 5.5 | BP20: 3.23 | BQ20: 0 | BR20: 0 | BS20: 0 | BT20: 0 | BU20: 0 | BV20: 0 | BW20: 0 | BX20: 250 | BY20: 0 | BZ20: 0 | CA20: 8.51 | CB20: CTBP | CC20: RJOP | CD20: 382.29 | CE20: 0 | CF20: 0 | CG20: 0 | CH20: 0 | CI20: 0 | CJ20: 0 | CK20: 0 | CN20: 0 | CO20: 0 | CP20: 0 | CQ20: 0 | CR20: 0 | CS20: 0 | CT20: 0 | CU20: 12.6 | CV20: MAPA: 161 | CW20: 0 | CY20: 18 | CZ20: MAPA: 162 | DA20: 0 | DE20: 0 | DF20: A. | DG20: PR | DH20: ARAUCARIA | DI20: 9026067267 | DJ20: (41 ) 38887555 | DK20: 0 | DL20: CTB | DM20: 54.25
A21: 2 | B21: CTB070717-1 | C21: NORMAL | D21: CTBP | E21: CTB | F21: 46238 | G21: DQB8989 | H21: 41260803098929000606570010000716131003663540 | I21: 05094003000155 | J21: COLSON DO BRASIL LTDA | K21: RUA DAS PALMEIRAS 350 | L21: CAPELA VELHA | M21: 002 | N21: ARAUCARIA | O21: PR | P21: 83705-500 | Q21: 05094003000155 | R21: COLSON DO BRASIL LTDA | S21: ARAUCARIA | T21: PR | U21: 05094003000155 | V21: COLSON DO BRASIL LTDA | W21: RUA DAS PALMEIRAS 350 | X21: CAPELA VELHA | Y21: ARAUCARIA | Z21: PR | AA21: (41 ) 38887555 | AC21: 09552066000169 | AD21: PIN PINHEIROS COMERCIO DE UTEN | AE21: 02 ZONA NORTE | AF21: SPOP | AG21: SAO PAULO | AH21: SP | AI21: 09552066000169 | AJ21: PIN PINHEIROS COMERCIO DE UTEN | AK21: SAO PAULO | AL21: SP | AM21: SPO | AN21: 000188793 | AO21: 41.67 | AP21: 0 | AQ21: 3 | AR21: 0 | AS21: CP | AT21: LIQUIDADO | AU21: 46253 | AV21: 397.86 | AW21: 001-DIVERSOS | AX21: 001-DIVERSOS | AY21: 1565.23 | AZ21: COMBINADA | BA21: CO3365274 | BB21: 397.86 | BC21: 350.12 | BD21: 397.86 | BE21: 47.74 | BF21: 0.12 | BG21: 0 | BH21: 41.67 | BI21: 56.8 | BJ21: 0 | BK21: 17 | BL21: 0 | BM21: 9.76 | BN21: 2.35 | BO21: 5.5 | BP21: 3.23 | BQ21: 0 | BR21: 0 | BS21: 0 | BT21: 0 | BU21: 0 | BV21: 0 | BW21: 0 | BX21: 250 | BY21: 0 | BZ21: 0 | CA21: 5.48 | CB21: CTBP | CC21: SPOP | CD21: 373.65 | CE21: 0 | CF21: 0 | CG21: 0 | CH21: 0 | CI21: 0 | CJ21: 0 | CK21: 0 | CN21: 0 | CO21: 0 | CP21: 0 | CQ21: 0 | CR21: 0 | CS21: 0 | CT21: 0 | CU21: 12 | CV21: MAPA: 161 | CW21: 0 | CY21: 18 | CZ21: MAPA: 161 | DA21: 0 | DE21: 0 | DF21: A. | DG21: PR | DH21: ARAUCARIA | DI21: 9026067267 | DJ21: (41 ) 38887555 | DK21: 0 | DL21: CTB | DM21: 47.74
A22: 2 | B22: CTB070718-0 | C22: NORMAL | D22: CTBP | E22: CTB | F22: 46238 | G22: DQB8989 | H22: 41260803098929000606570010000716141003663555 | I22: 05094003000155 | J22: COLSON DO BRASIL LTDA | K22: RUA DAS PALMEIRAS 350 | L22: CAPELA VELHA | M22: 002 | N22: ARAUCARIA | O22: PR | P22: 83705-500 | Q22: 05094003000155 | R22: COLSON DO BRASIL LTDA | S22: ARAUCARIA | T22: PR | U22: 05094003000155 | V22: COLSON DO BRASIL LTDA | W22: RUA DAS PALMEIRAS 350 | X22: CAPELA VELHA | Y22: ARAUCARIA | Z22: PR | AA22: (41 ) 38887555 | AC22: 05586184000137 | AD22: FALCARE EQUIPAMENTOS INDUSTRIAIS LTDA | AE22: 11 ABCD | AF22: SPOP | AG22: SAO CAETANO DO SUL | AH22: SP | AI22: 05586184000137 | AJ22: FALCARE EQUIPAMENTOS INDUSTRIAIS LTDA | AK22: SAO CAETANO DO SUL | AL22: SP | AM22: SPO | AN22: 000188795 | AO22: 32.8 | AP22: 0 | AQ22: 4 | AR22: 0 | AS22: CP | AT22: LIQUIDADO | AU22: 46253 | AV22: 133.48 | AW22: 001-DIVERSOS | AX22: 001-DIVERSOS | AY22: 5035.5 | AZ22: COMBINADA | BA22: CO3365274 | BB22: 133.48 | BC22: 117.46 | BD22: 133.48 | BE22: 16.02 | BF22: 0.12 | BG22: 0 | BH22: 32.8 | BI22: 56.8 | BJ22: 0 | BK22: 17 | BL22: 0 | BM22: 9.76 | BN22: 7.55 | BO22: 5.5 | BP22: 3.23 | BQ22: 0 | BR22: 0 | BS22: 0 | BT22: 0 | BU22: 0 | BV22: 0 | BW22: 0 | BX22: 0 | BY22: 0 | BZ22: 0 | CA22: 17.62 | CB22: CTBP | CC22: SPOP | CD22: 415.44 | CE22: 0 | CF22: 0 | CG22: 0 | CH22: 0 | CI22: 0 | CJ22: 0 | CK22: 0 | CN22: 0 | CO22: 0 | CP22: 0 | CQ22: 0 | CR22: 0 | CS22: 0 | CT22: 0 | CU22: 12 | CV22: MAPA: 161 | CW22: 0 | CY22: 18 | CZ22: MAPA: 161 | DA22: 0 | DE22: 0 | DF22: A. | DG22: PR | DH22: ARAUCARIA | DI22: 9026067267 | DJ22: (41 ) 38887555 | DK22: 0 | DL22: CTB | DM22: 16.02
A23: 2 | B23: CTB070719-8 | C23: NORMAL | D23: CTBP | E23: CTB | F23: 46238 | G23: DQB8989 | H23: 41260803098929000606570010000716151003663560 | I23: 05094003000155 | J23: COLSON DO BRASIL LTDA | K23: RUA DAS PALMEIRAS 350 | L23: CAPELA VELHA | M23: 002 | N23: ARAUCARIA | O23: PR | P23: 83705-500 | Q23: 05094003000155 | R23: COLSON DO BRASIL LTDA | S23: ARAUCARIA | T23: PR | U23: 05094003000155 | V23: COLSON DO BRASIL LTDA | W23: RUA DAS PALMEIRAS 350 | X23: CAPELA VELHA | Y23: ARAUCARIA | Z23: PR | AA23: (41 ) 38887555 | AC23: 48960632000123 | AD23: VARGEM PEQUENA ALUGUEL DE EQUIPAMEN | AE23: RIO RIO DE JANEIRO | AF23: RJOP | AG23: RIO DE JANEIRO | AH23: RJ | AI23: 48960632000123 | AJ23: VARGEM PEQUENA ALUGUEL DE EQUIPAMEN | AK23: RIO DE JANEIRO | AL23: RJ | AM23: RJO | AN23: 000188774 | AO23: 1600 | AP23: 0 | AQ23: 100 | AR23: 0 | AS23: CP | AT23: LIQUIDADO | AU23: 46253 | AV23: 2038.49 | AW23: 001-DIVERSOS | AX23: 001-DIVERSOS | AY23: 47143.95 | AZ23: COMBINADA | BA23: CO3365267 | BB23: 2038.49 | BC23: 1793.87 | BD23: 2038.49 | BE23: 244.62 | BF23: 0.12 | BG23: 0 | BH23: 1600 | BI23: 1440.16 | BJ23: 0 | BK23: 17 | BL23: 0 | BM23: 9.76 | BN23: 70.72 | BO23: 88 | BP23: 3.23 | BQ23: 0 | BR23: 0 | BS23: 0 | BT23: 0 | BU23: 0 | BV23: 0 | BW23: 0 | BX23: 0 | BY23: 0 | BZ23: 0 | CA23: 165 | CB23: CTBP | CC23: RJOP | CD23: 4462.54 | CE23: 0 | CF23: 0 | CG23: 0 | CH23: 0 | CI23: 0 | CJ23: 0 | CK23: 0 | CN23: 0 | CO23: 0 | CP23: 0 | CQ23: 0 | CR23: 0 | CS23: 0 | CT23: 0 | CU23: 240 | CV23: MAPA: 161 | CW23: 0 | CY23: 288 | CZ23: MAPA: 161 | DA23: 0 | DE23: 0 | DF23: A. | DG23: PR | DH23: ARAUCARIA | DI23: 9026067267 | DJ23: (41 ) 38887555 | DK23: 0 | DL23: CTB | DM23: 244.62
A24: 2 | B24: CTB070760-1 | C24: COMPLEMENTAR FRETE | D24: CTBP | E24: CTB | F24: 46239 | G24: AZS7C31 | H24: 41260803098929000606570010000716561003667992 | I24: 05094003000155 | J24: COLSON DO BRASIL LTDA | K24: RUA DAS PALMEIRAS 350 | L24: CAPELA VELHA | M24: 002 | N24: ARAUCARIA | O24: PR | P24: 83705-500 | Q24: 05094003000155 | R24: COLSON DO BRASIL LTDA | S24: ARAUCARIA | T24: PR | U24: 05094003000155 | V24: COLSON DO BRASIL LTDA | W24: RUA DAS PALMEIRAS 350 | X24: CAPELA VELHA | Y24: ARAUCARIA | Z24: PR | AA24: (41 ) 38887555 | AC24: 23476033002909 | AD24: BMB MATERIAL DE CONSTRUCAO SA | AE24: 05 ZONA LESTE | AF24: SPOP | AG24: SAO PAULO | AH24: SP | AI24: 23476033002909 | AJ24: BMB MATERIAL DE CONSTRUCAO SA | AK24: SAO PAULO | AL24: SP | AM24: SPO | AN24: 000187693 | AO24: 49.28 | AP24: 0 | AQ24: 3 | AR24: 0 | AS24: CP | AT24: LIQUIDADO | AU24: 46253 | AV24: 284.09 | AW24: 001-DIVERSOS | AX24: 001-DIVERSOS | AY24: 1473.07 | AZ24: COMPLEMENTAR DE FRETE | BB24: 284.09 | BC24: 250 | BD24: 284.09 | BE24: 34.09 | BF24: 0.12 | BG24: 0 | BH24: 49.28 | BI24: 0 | BJ24: 250 | BK24: 0 | BL24: 0 | BM24: 0 | BN24: 0 | BO24: 0 | BP24: 0 | BQ24: 0 | BR24: 0 | BS24: 0 | BT24: 0 | BU24: 0 | BV24: 0 | BW24: 0 | BX24: 0 | BY24: 0 | BZ24: 0 | CA24: 0 | CB24: CTBP | CC24: SPOP | CD24: 372.72 | CE24: 0 | CF24: 0 | CG24: 0 | CH24: 0 | CI24: 0 | CJ24: 0 | CK24: 0 | CN24: 0 | CO24: 0 | CP24: 0 | CQ24: 0 | CR24: 0 | CS24: 0 | CT24: 0 | CU24: 0 | CV24: MAPA: 0 | CW24: 0 | CY24: 0 | CZ24: MAPA: 0 | DA24: 0 | DE24: 0 | DF24: A. | DG24: PR | DH24: ARAUCARIA | DI24: 9026067267 | DJ24: (41 ) 38887555 | DK24: 0 | DL24: CTB | DM24: 34.09
A25: 2 | B25: CTB070815-1 | C25: NORMAL | D25: CTBP | E25: CTB | F25: 46239 | G25: BFE7A89 | H25: 41260803098929000606570010000717111003674151 | I25: 05094003000155 | J25: COLSON DO BRASIL LTDA | K25: RUA DAS PALMEIRAS 350 | L25: CAPELA VELHA | M25: 002 | N25: ARAUCARIA | O25: PR | P25: 83705-500 | Q25: 05094003000155 | R25: COLSON DO BRASIL LTDA | S25: ARAUCARIA | T25: PR | U25: 05094003000155 | V25: COLSON DO BRASIL LTDA | W25: RUA DAS PALMEIRAS 350 | X25: CAPELA VELHA | Y25: ARAUCARIA | Z25: PR | AA25: (41 ) 38887555 | AC25: 43011160000149 | AD25: ADELMO SILVA SANTOS EQUIPAMENTOS | AE25: 11 ABCD | AF25: SPOP | AG25: DIADEMA | AH25: SP | AI25: 43011160000149 | AJ25: ADELMO SILVA SANTOS EQUIPAMENTOS | AK25: DIADEMA | AL25: SP | AM25: SPO | AN25: 000188960 | AO25: 35.061 | AP25: 0 | AQ25: 3 | AR25: 0 | AS25: CP | AT25: LIQUIDADO | AU25: 46253 | AV25: 113.5 | AW25: 001-DIVERSOS | AX25: 001-DIVERSOS | AY25: 1517.68 | AZ25: COMBINADA | BA25: CO3365274 | BB25: 113.5 | BC25: 99.88 | BD25: 113.5 | BE25: 13.62 | BF25: 0.12 | BG25: 0 | BH25: 35.061 | BI25: 56.8 | BJ25: 0 | BK25: 17 | BL25: 0 | BM25: 9.76 | BN25: 2.28 | BO25: 5.5 | BP25: 3.23 | BQ25: 0 | BR25: 0 | BS25: 0 | BT25: 0 | BU25: 0 | BV25: 0 | BW25: 0 | BX25: 0 | BY25: 0 | BZ25: 0 | CA25: 5.31 | CB25: CTBP | CC25: SPOP | CD25: 373.23 | CE25: 0 | CF25: 0 | CG25: 0 | CH25: 0 | CI25: 0 | CJ25: 0 | CK25: 0 | CN25: 0 | CO25: 0 | CP25: 0 | CQ25: 0 | CR25: 0 | CS25: 0 | CT25: 0 | CU25: 12 | CV25: MAPA: 161 | CW25: 0 | CY25: 18 | CZ25: MAPA: 161 | DA25: 0 | DE25: 0 | DF25: A. | DG25: PR | DH25: ARAUCARIA | DI25: 9026067267 | DJ25: (41 ) 38887555 | DK25: 0 | DL25: CTB | DM25: 13.62
A26: 2 | B26: CTB070816-0 | C26: NORMAL | D26: CTBP | E26: CTB | F26: 46239 | G26: BFE7A89 | H26: 41260803098929000606570010000717121003674167 | I26: 05094003000155 | J26: COLSON DO BRASIL LTDA | K26: RUA DAS PALMEIRAS 350 | L26: CAPELA VELHA | M26: 002 | N26: ARAUCARIA | O26: PR | P26: 83705-500 | Q26: 05094003000155 | R26: COLSON DO BRASIL LTDA | S26: ARAUCARIA | T26: PR | U26: 05094003000155 | V26: COLSON DO BRASIL LTDA | W26: RUA DAS PALMEIRAS 350 | X26: CAPELA VELHA | Y26: ARAUCARIA | Z26: PR | AA26: (41 ) 38887555 | AC26: 18712769000106 | AD26: MANHUACU LOCACAO DE EQUIP LTDA | AE26: 369 | AF26: GVRP | AG26: MANHUACU | AH26: MG | AI26: 18712769000106 | AJ26: MANHUACU LOCACAO DE EQUIP LTDA | AK26: MANHUACU | AL26: MG | AM26: GVR | AN26: 000188916 | AO26: 149.4 | AP26: 0 | AQ26: 9 | AR26: 0 | AS26: CP | AT26: LIQUIDADO | AU26: 46253 | AV26: 268.61 | AW26: 001-DIVERSOS | AX26: 001-DIVERSOS | AY26: 3212.6 | AZ26: COMBINADA | BA26: CO3365294 | BB26: 268.61 | BC26: 236.38 | BD26: 268.61 | BE26: 32.23 | BF26: 0.12 | BG26: 0 | BH26: 149.4 | BI26: 179.33 | BJ26: 0 | BK26: 17 | BL26: 0 | BM26: 9.76 | BN26: 4.82 | BO26: 11 | BP26: 3.23 | BQ26: 0 | BR26: 0 | BS26: 0 | BT26: 0 | BU26: 0 | BV26: 0 | BW26: 0 | BX26: 0 | BY26: 0 | BZ26: 0 | CA26: 11.24 | CB26: CTBP | CC26: RWNI | CD26: 391.79 | CE26: 0 | CF26: 0 | CG26: 0 | CH26: 0 | CI26: 0 | CJ26: 0 | CK26: 0 | CN26: 0 | CO26: 0 | CP26: 0 | CQ26: 0 | CR26: 0 | CS26: 0 | CT26: 0 | CU26: 22.41 | CV26: MAPA: 161 | CW26: 0 | CY26: 103.01 | CZ26: FATURA: 12222 | DA26: 103.01 | DB26: 012222 | DE26: 0 | DF26: A. | DG26: PR | DH26: ARAUCARIA | DI26: 9026067267 | DJ26: (41 ) 38887555 | DK26: 0 | DL26: CTB | DM26: 32.23
A27: 2 | B27: CTB070817-8 | C27: NORMAL | D27: CTBP | E27: CTB | F27: 46239 | G27: BFE7A89 | H27: 41260803098929000606570010000717131003674172 | I27: 05094003000155 | J27: COLSON DO BRASIL LTDA | K27: RUA DAS PALMEIRAS 350 | L27: CAPELA VELHA | M27: 002 | N27: ARAUCARIA | O27: PR | P27: 83705-500 | Q27: 05094003000155 | R27: COLSON DO BRASIL LTDA | S27: ARAUCARIA | T27: PR | U27: 05094003000155 | V27: COLSON DO BRASIL LTDA | W27: RUA DAS PALMEIRAS 350 | X27: CAPELA VELHA | Y27: ARAUCARIA | Z27: PR | AA27: (41 ) 38887555 | AC27: 23151087000284 | AD27: CELIO GROSSI FERRGS LTDA | AE27: 365 | AF27: TAMR | AG27: VICOSA | AH27: MG | AI27: 23151087000284 | AJ27: CELIO GROSSI FERRGS LTDA | AK27: VICOSA | AL27: MG | AM27: TAM | AN27: 000188859 | AO27: 200.55 | AP27: 0 | AQ27: 21 | AR27: 0 | AS27: CP | AT27: LIQUIDADO | AU27: 46253 | AV27: 321.93 | AW27: 001-DIVERSOS | AX27: 001-DIVERSOS | AY27: 6353.02 | AZ27: COMBINADA | BA27: CO3365280 | BB27: 321.93 | BC27: 283.3 | BD27: 321.93 | BE27: 38.63 | BF27: 0.12 | BG27: 0 | BH27: 200.55 | BI27: 205.04 | BJ27: 0 | BK27: 17 | BL27: 0 | BM27: 9.76 | BN27: 9.53 | BO27: 16.5 | BP27: 3.23 | BQ27: 0 | BR27: 0 | BS27: 0 | BT27: 0 | BU27: 0 | BV27: 0 | BW27: 0 | BX27: 0 | BY27: 0 | BZ27: 0 | CA27: 22.24 | CB27: CTBP | CC27: TAMR | CD27: 433.98 | CE27: 0 | CF27: 0 | CG27: 0 | CH27: 0 | CI27: 0 | CJ27: 0 | CK27: 0 | CN27: 0 | CO27: 0 | CP27: 0 | CQ27: 0 | CR27: 0 | CS27: 0 | CT27: 0 | CU27: 30.08 | CV27: MAPA: 161 | CW27: 0 | CY27: 100.28 | CZ27: FATURA: 21534 | DA27: 100.28 | DB27: 021534 | DE27: 0 | DF27: A. | DG27: PR | DH27: ARAUCARIA | DI27: 9026067267 | DJ27: (41 ) 38887555 | DK27: 0 | DL27: CTB | DM27: 38.63
A28: 2 | B28: CTB070818-6 | C28: NORMAL | D28: CTBP | E28: CTB | F28: 46239 | G28: BFE7A89 | H28: 41260803098929000606570010000717141003674188 | I28: 05094003000155 | J28: COLSON DO BRASIL LTDA | K28: RUA DAS PALMEIRAS 350 | L28: CAPELA VELHA | M28: 002 | N28: ARAUCARIA | O28: PR | P28: 83705-500 | Q28: 05094003000155 | R28: COLSON DO BRASIL LTDA | S28: ARAUCARIA | T28: PR | U28: 05094003000155 | V28: COLSON DO BRASIL LTDA | W28: RUA DAS PALMEIRAS 350 | X28: CAPELA VELHA | Y28: ARAUCARIA | Z28: PR | AA28: (41 ) 38887555 | AC28: 11601412000101 | AD28: BAZAR E ARMARINHO TRES IRMAOS LTDA ME | AE28: RIO RIO DE JANEIRO | AF28: RJOP | AG28: RIO DE JANEIRO | AH28: RJ | AI28: 11601412000101 | AJ28: BAZAR E ARMARINHO TRES IRMAOS LTDA ME | AK28: RIO DE JANEIRO | AL28: RJ | AM28: RJO | AN28: 000188855 | AO28: 137.4 | AP28: 0 | AQ28: 15 | AR28: 0 | AS28: CP | AT28: LIQUIDADO | AU28: 46253 | AV28: 211.63 | AW28: 001-DIVERSOS | AX28: 054-PNEUS E CAMARAS DE AR | AY28: 4315.19 | AZ28: COMBINADA | BA28: CO3365267 | BB28: 211.63 | BC28: 186.23 | BD28: 211.63 | BE28: 25.4 | BF28: 0.12 | BG28: 0 | BH28: 137.4 | BI28: 123.67 | BJ28: 0 | BK28: 17 | BL28: 0 | BM28: 9.76 | BN28: 6.47 | BO28: 11 | BP28: 3.23 | BQ28: 0 | BR28: 0 | BS28: 0 | BT28: 0 | BU28: 0 | BV28: 0 | BW28: 0 | BX28: 0 | BY28: 0 | BZ28: 0 | CA28: 15.1 | CB28: CTBP | CC28: RJOP | CD28: 406.12 | CE28: 0 | CF28: 0 | CG28: 0 | CH28: 0 | CI28: 0 | CJ28: 0 | CK28: 0 | CN28: 0 | CO28: 0 | CP28: 0 | CQ28: 0 | CR28: 0 | CS28: 0 | CT28: 0 | CU28: 20.61 | CV28: MAPA: 161 | CW28: 0 | CY28: 24.73 | CZ28: MAPA: 161 | DA28: 0 | DE28: 0 | DF28: A. | DG28: PR | DH28: ARAUCARIA | DI28: 9026067267 | DJ28: (41 ) 38887555 | DK28: 0 | DL28: CTB | DM28: 25.4
A29: 2 | B29: CTB070819-4 | C29: NORMAL | D29: CTBP | E29: CTB | F29: 46239 | G29: BFE7A89 | H29: 41260803098929000606570010000717151003674193 | I29: 05094003000155 | J29: COLSON DO BRASIL LTDA | K29: RUA DAS PALMEIRAS 350 | L29: CAPELA VELHA | M29: 002 | N29: ARAUCARIA | O29: PR | P29: 83705-500 | Q29: 05094003000155 | R29: COLSON DO BRASIL LTDA | S29: ARAUCARIA | T29: PR | U29: 05094003000155 | V29: COLSON DO BRASIL LTDA | W29: RUA DAS PALMEIRAS 350 | X29: CAPELA VELHA | Y29: ARAUCARIA | Z29: PR | AA29: (41 ) 38887555 | AC29: 21020745000192 | AD29: SUAVIDA EPIS EIRELI 950019 | AE29: RIO RIO DE JANEIRO | AF29: RJOP | AG29: RIO DE JANEIRO | AH29: RJ | AI29: 21020745000192 | AJ29: SUAVIDA EPIS EIRELI 950019 | AK29: RIO DE JANEIRO | AL29: RJ | AM29: RJO | AN29: 000188815 | AO29: 149.23 | AP29: 0 | AQ29: 21 | AR29: 0 | AS29: CP | AT29: LIQUIDADO | AU29: 46253 | AV29: 217.86 | AW29: 001-DIVERSOS | AX29: 001-DIVERSOS | AY29: 3281.56 | AZ29: COMBINADA | BA29: CO3365267 | BB29: 217.86 | BC29: 191.72 | BD29: 217.86 | BE29: 26.14 | BF29: 0.12 | BG29: 0 | BH29: 149.23 | BI29: 134.32 | BJ29: 0 | BK29: 17 | BL29: 0 | BM29: 9.76 | BN29: 4.92 | BO29: 11 | BP29: 3.23 | BQ29: 0 | BR29: 0 | BS29: 0 | BT29: 0 | BU29: 0 | BV29: 0 | BW29: 0 | BX29: 0 | BY29: 0 | BZ29: 0 | CA29: 11.49 | CB29: CTBP | CC29: RJOP | CD29: 392.68 | CE29: 0 | CF29: 0 | CG29: 0 | CH29: 0 | CI29: 0 | CJ29: 0 | CK29: 0 | CN29: 0 | CO29: 0 | CP29: 0 | CQ29: 0 | CR29: 0 | CS29: 0 | CT29: 0 | CU29: 22.38 | CV29: MAPA: 161 | CW29: 0 | CY29: 26.86 | CZ29: MAPA: 161 | DA29: 0 | DE29: 0 | DF29: A. | DG29: PR | DH29: ARAUCARIA | DI29: 9026067267 | DJ29: (41 ) 38887555 | DK29: 0 | DL29: CTB | DM29: 26.14
A30: 2 | B30: CTB070820-8 | C30: NORMAL | D30: CTBP | E30: CTB | F30: 46239 | G30: BFE7A89 | H30: 41260803098929000606570010000717161003674204 | I30: 05094003000155 | J30: COLSON DO BRASIL LTDA | K30: RUA DAS PALMEIRAS 350 | L30: CAPELA VELHA | M30: 002 | N30: ARAUCARIA | O30: PR | P30: 83705-500 | Q30: 05094003000155 | R30: COLSON DO BRASIL LTDA | S30: ARAUCARIA | T30: PR | U30: 05094003000155 | V30: COLSON DO BRASIL LTDA | W30: RUA DAS PALMEIRAS 350 | X30: CAPELA VELHA | Y30: ARAUCARIA | Z30: PR | AA30: (41 ) 38887555 | AC30: 16691059000103 | AD30: FAMART DISTRIBUIDORA DE FERRAGENS LTDA | AE30: 257 | AF30: MVGP | AG30: PETROPOLIS | AH30: RJ | AI30: 16691059000103 | AJ30: FAMART DISTRIBUIDORA DE FERRAGENS LTDA | AK30: PETROPOLIS | AL30: RJ | AM30: MVG | AN30: 000188909 | AO30: 271.414 | AP30: 0 | AQ30: 23 | AR30: 0 | AS30: CP | AT30: LIQUIDADO | AU30: 46253 | AV30: 737.32 | AW30: 001-DIVERSOS | AX30: 054-PNEUS E CAMARAS DE AR | AY30: 6960.96 | AZ30: COMBINADA | BA30: CO3365270 | BB30: 737.32 | BC30: 648.84 | BD30: 737.32 | BE30: 88.48 | BF30: 0.12 | BG30: 0 | BH30: 271.414 | BI30: 317.55 | BJ30: 0 | BK30: 17 | BL30: 0 | BM30: 9.76 | BN30: 10.44 | BO30: 16.5 | BP30: 3.23 | BQ30: 0 | BR30: 0 | BS30: 0 | BT30: 0 | BU30: 0 | BV30: 0 | BW30: 0 | BX30: 250 | BY30: 0 | BZ30: 0 | CA30: 24.36 | CB30: CTBP | CC30: ITAI | CD30: 619.02 | CE30: 0 | CF30: 0 | CG30: 0 | CH30: 0 | CI30: 0 | CJ30: 0 | CK30: 0 | CN30: 0 | CO30: 0 | CP30: 0 | CQ30: 0 | CR30: 0 | CS30: 0 | CT30: 0 | CU30: 40.71 | CV30: MAPA: 161 | CW30: 0 | CY30: 408.52 | CZ30: FATURA: 17774 | DA30: 324.32 | DB30: 017774 | DE30: 0 | DF30: A. | DG30: PR | DH30: ARAUCARIA | DI30: 9026067267 | DJ30: (41 ) 38887555 | DK30: 0 | DL30: CTB | DM30: 88.48
A31: 2 | B31: CTB070821-6 | C31: NORMAL | D31: CTBP | E31: CTB | F31: 46239 | G31: BFE7A89 | H31: 41260803098929000606570010000717171003674210 | I31: 05094003000155 | J31: COLSON DO BRASIL LTDA | K31: RUA DAS PALMEIRAS 350 | L31: CAPELA VELHA | M31: 002 | N31: ARAUCARIA | O31: PR | P31: 83705-500 | Q31: 05094003000155 | R31: COLSON DO BRASIL LTDA | S31: ARAUCARIA | T31: PR | U31: 05094003000155 | V31: COLSON DO BRASIL LTDA | W31: RUA DAS PALMEIRAS 350 | X31: CAPELA VELHA | Y31: ARAUCARIA | Z31: PR | AA31: (41 ) 38887555 | AC31: 15096516000159 | AD31: MOUTINHO REIS SUPORTE EM EQUIPAMENT | AE31: 10 BARUERI | AF31: SPOP | AG31: BARUERI | AH31: SP | AI31: 15096516000159 | AJ31: MOUTINHO REIS SUPORTE EM EQUIPAMENT | AK31: BARUERI | AL31: SP | AM31: SPO | AN31: 000188923 | AO31: 23.8 | AP31: 0 | AQ31: 2 | AR31: 0 | AS31: CP | AT31: LIQUIDADO | AU31: 46253 | AV31: 114.75 | AW31: 001-DIVERSOS | AX31: 001-DIVERSOS | AY31: 3458.05 | AZ31: COMBINADA | BA31: CO3365274 | BB31: 114.75 | BC31: 100.98 | BD31: 114.75 | BE31: 13.77 | BF31: 0.12 | BG31: 0 | BH31: 23.8 | BI31: 48.2 | BJ31: 0 | BK31: 17 | BL31: 0 | BM31: 9.76 | BN31: 5.19 | BO31: 5.5 | BP31: 3.23 | BQ31: 0 | BR31: 0 | BS31: 0 | BT31: 0 | BU31: 0 | BV31: 0 | BW31: 0 | BX31: 0 | BY31: 0 | BZ31: 0 | CA31: 12.1 | CB31: CTBP | CC31: SPOP | CD31: 395.01 | CE31: 0 | CF31: 0 | CG31: 0 | CH31: 0 | CI31: 0 | CJ31: 0 | CK31: 0 | CN31: 0 | CO31: 0 | CP31: 0 | CQ31: 0 | CR31: 0 | CS31: 0 | CT31: 0 | CU31: 12 | CV31: MAPA: 161 | CW31: 0 | CY31: 18 | CZ31: MAPA: 161 | DA31: 0 | DE31: 0 | DF31: A. | DG31: PR | DH31: ARAUCARIA | DI31: 9026067267 | DJ31: (41 ) 38887555 | DK31: 0 | DL31: CTB | DM31: 13.77
A32: 2 | B32: CTB070822-4 | C32: NORMAL | D32: CTBP | E32: CTB | F32: 46239 | G32: BFE7A89 | H32: 41260803098929000606570010000717181003674225 | I32: 05094003000155 | J32: COLSON DO BRASIL LTDA | K32: RUA DAS PALMEIRAS 350 | L32: CAPELA VELHA | M32: 002 | N32: ARAUCARIA | O32: PR | P32: 83705-500 | Q32: 05094003000155 | R32: COLSON DO BRASIL LTDA | S32: ARAUCARIA | T32: PR | U32: 05094003000155 | V32: COLSON DO BRASIL LTDA | W32: RUA DAS PALMEIRAS 350 | X32: CAPELA VELHA | Y32: ARAUCARIA | Z32: PR | AA32: (41 ) 38887555 | AC32: 30999394000102 | AD32: TECNO PRO PARAFUSOS E FERRAMEN | AE32: 332 | AF32: BHZP | AG32: LAGOA SANTA | AH32: MG | AI32: 30999394000102 | AJ32: TECNO PRO PARAFUSOS E FERRAMEN | AK32: LAGOA SANTA | AL32: MG | AM32: BHZ | AN32: 000188913 | AO32: 79.02 | AP32: 0 | AQ32: 11 | AR32: 0 | AS32: CP | AT32: LIQUIDADO | AU32: 46253 | AV32: 171.99 | AW32: 001-DIVERSOS | AX32: 001-DIVERSOS | AY32: 2932.62 | AZ32: COMBINADA | BA32: CO3365271 | BB32: 171.99 | BC32: 151.35 | BD32: 171.99 | BE32: 20.64 | BF32: 0.12 | BG32: 0 | BH32: 79.02 | BI32: 101.2 | BJ32: 0 | BK32: 17 | BL32: 0 | BM32: 9.76 | BN32: 4.4 | BO32: 5.5 | BP32: 3.23 | BQ32: 0 | BR32: 0 | BS32: 0 | BT32: 0 | BU32: 0 | BV32: 0 | BW32: 0 | BX32: 0 | BY32: 0 | BZ32: 0 | CA32: 10.26 | CB32: CTBP | CC32: BHZP | CD32: 388.15 | CE32: 0 | CF32: 0 | CG32: 0 | CH32: 0 | CI32: 0 | CJ32: 0 | CK32: 0 | CN32: 0 | CO32: 0 | CP32: 0 | CQ32: 0 | CR32: 0 | CS32: 0 | CT32: 0 | CU32: 12 | CV32: MAPA: 161 | CW32: 0 | CY32: 15 | CZ32: MAPA: 161 | DA32: 0 | DE32: 0 | DF32: A. | DG32: PR | DH32: ARAUCARIA | DI32: 9026067267 | DJ32: (41 ) 38887555 | DK32: 0 | DL32: CTB | DM32: 20.64
A33: 2 | B33: CTB070823-2 | C33: NORMAL | D33: CTBP | E33: CTB | F33: 46239 | G33: BFE7A89 | H33: 41260803098929000606570010000717191003674230 | I33: 05094003000155 | J33: COLSON DO BRASIL LTDA | K33: RUA DAS PALMEIRAS 350 | L33: CAPELA VELHA | M33: 002 | N33: ARAUCARIA | O33: PR | P33: 83705-500 | Q33: 05094003000155 | R33: COLSON DO BRASIL LTDA | S33: ARAUCARIA | T33: PR | U33: 05094003000155 | V33: COLSON DO BRASIL LTDA | W33: RUA DAS PALMEIRAS 350 | X33: CAPELA VELHA | Y33: ARAUCARIA | Z33: PR | AA33: (41 ) 38887555 | AC33: 18565489000104 | AD33: BARROS E BEIRAL ATACADO E VAREJO LTDA | AE33: 282 | AF33: RCGR | AG33: SAO FRANCISCO DE ITABAPOANA | AH33: RJ | AI33: 18565489000104 | AJ33: BARROS E BEIRAL ATACADO E VAREJO LTDA | AK33: SAO FRANCISCO DE ITABAPOANA | AL33: RJ | AM33: RCG | AN33: 000188919 | AO33: 458.155 | AP33: 0 | AQ33: 35 | AR33: 0 | AS33: CP | AT33: LIQUIDADO | AU33: 46253 | AV33: 760.59 | AW33: 001-DIVERSOS | AX33: 054-PNEUS E CAMARAS DE AR | AY33: 15156.76 | AZ33: COMBINADA | BA33: CO3365270 | BB33: 760.59 | BC33: 669.32 | BD33: 760.59 | BE33: 91.27 | BF33: 0.12 | BG33: 0 | BH33: 458.155 | BI33: 536.04 | BJ33: 0 | BK33: 17 | BL33: 0 | BM33: 9.76 | BN33: 22.74 | BO33: 27.5 | BP33: 3.23 | BQ33: 0 | BR33: 0 | BS33: 0 | BT33: 0 | BU33: 0 | BV33: 0 | BW33: 0 | BX33: 0 | BY33: 0 | BZ33: 0 | CA33: 53.05 | CB33: CTBP | CC33: ITAI | CD33: 1192.52 | CE33: 0 | CF33: 0 | CG33: 0 | CH33: 0 | CI33: 0 | CJ33: 0 | CK33: 0 | CN33: 0 | CO33: 0 | CP33: 0 | CQ33: 0 | CR33: 0 | CS33: 0 | CT33: 0 | CU33: 68.72 | CV33: MAPA: 161 | CW33: 0 | CY33: 254.46 | CZ33: FATURA: 12167 | DA33: 286.41 | DB33: 012167 | DE33: 0 | DF33: A. | DG33: PR | DH33: ARAUCARIA | DI33: 9026067267 | DJ33: (41 ) 38887555 | DK33: 0 | DL33: CTB | DM33: 91.27
